<?xml version='1.0' encoding='utf-8'?>
<mujoco model="open_manipulator_y_maze">
  <compiler angle="radian" meshdir="assets/" />
  <option cone="elliptic" impratio="10" />
  <statistic center="0.32 0 0.35" extent="1.0" />
  <visual>
    <headlight diffuse="0.6 0.6 0.6" ambient="0.3 0.3 0.3" specular="0 0 0" />
    <rgba haze="0.15 0.25 0.35 1" />
    <global azimuth="120" elevation="-20" />
  </visual>
  <asset>
    <material name="black" rgba="0.1 0.1 0.1 1" />
    <mesh name="base_unit" file="base_unit.stl" scale="0.001 0.001 0.001" />
    <mesh name="link1" file="link1.stl" scale="0.001 0.001 0.001" />
    <mesh name="link2" file="link2.stl" scale="0.001 0.001 0.001" />
    <mesh name="link3" file="link3.stl" scale="0.001 0.001 0.001" />
    <mesh name="link4" file="link4.stl" scale="0.001 0.001 0.001" />
    <mesh name="link5" file="link5.stl" scale="0.001 0.001 0.001" />
    <mesh name="link6" file="link6.stl" scale="0.001 0.001 0.001" />
    <mesh name="flange" file="flange.stl" scale="0.001 0.001 0.001" />
    <mesh name="base" file="base.stl" scale="0.001 0.001 0.001" />
    <mesh name="r1" file="r1.stl" scale="0.001 0.001 0.001" />
    <mesh name="r2" file="r2.stl" scale="0.001 0.001 0.001" />
    <mesh name="l1" file="l1.stl" scale="0.001 0.001 0.001" />
    <mesh name="l2" file="l2.stl" scale="0.001 0.001 0.001" />
    <texture type="skybox" builtin="gradient" rgb1="0.3 0.5 0.7" rgb2="0 0 0" width="512" height="3072" />
    <texture type="2d" name="groundplane" builtin="checker" mark="edge" rgb1="0.2 0.3 0.4" rgb2="0.1 0.2 0.3" markrgb="0.8 0.8 0.8" width="300" height="300" />
    <material name="groundplane" texture="groundplane" texuniform="true" texrepeat="5 5" reflectance="0.2" />
    <material name="tip_metal" rgba="0.85 0.80 0.70 1" specular="0.7" shininess="0.8" />
    <material name="tip_dark" rgba="0.04 0.04 0.04 1" />
    <material name="maze_floor" rgba="0.34 0.34 0.34 1" />
    <material name="maze_wall" rgba="0.52 0.72 0.50 0.9" />
  <material name="planned_path" rgba="0.05 0.45 1.0 0.85" emission="0.15" /><material name="planned_waypoint" rgba="1.0 0.78 0.05 1.0" emission="0.25" /><material name="planned_start" rgba="0.05 1.0 0.2 1.0" emission="0.25" /><material name="planned_goal" rgba="1.0 0.12 0.08 1.0" emission="0.25" /><material name="los_path" rgba="0.75 0.10 1.0 0.85" emission="0.20" /><material name="los_waypoint" rgba="1.0 0.20 0.85 1.0" emission="0.30" /></asset>
  <default>
    <default class="DY_80">
      <joint frictionloss="0.1" armature="0.1" />
      <position kp="1000.0" dampratio="1.0" forcerange="-61.4 61.4" />
      <default class="Joint1">
        <joint axis="0 0 1" range="-6.283185 6.283185" />
      </default>
      <default class="Joint2">
        <joint axis="0 1 0" range="-6.283185 6.283185" />
      </default>
    </default>
    <default class="DY_70">
      <joint frictionloss="0.1" armature="0.1" />
      <position kp="1000.0" dampratio="1.0" forcerange="-31.7 31.7" />
      <default class="Joint3">
        <joint axis="0 1 0" range="-2.617994 2.617994" />
      </default>
      <default class="Joint4">
        <joint axis="0 1 0" range="-6.283185 6.283185" />
      </default>
      <default class="Joint5">
        <joint axis="0 0 1" range="-6.283185 6.283185" />
      </default>
      <default class="Joint6">
        <joint axis="0 1 0" range="-6.283185 6.283185" />
      </default>
    </default>
    <default class="DX">
      <joint frictionloss="0.1" armature="0.1" damping="1.0" />
      <position kp="50" dampratio="1" forcerange="-3.5 3.5" />
      <default class="Gripper">
        <joint axis="1 0 0" range="0 1.1" />
      </default>
      <default class="Gripper_mimic">
        <joint axis="1 0 0" range="-1.1 0" />
      </default>
      <default class="Gripper_mimic_pos">
        <joint axis="1 0 0" range="0 1.1" />
      </default>
    </default>
    <default class="visual">
      <geom type="mesh" contype="0" conaffinity="0" density="0" group="2" material="black" />
    </default>
    <default class="collision">
      <geom group="3" type="mesh" material="black" contype="0" conaffinity="0" />
    </default>
  </default>
  <worldbody>
    <light name="main_light" pos="0 0 1.5" dir="0 0 -1" directional="true" />
    <geom name="floor" size="0 0 0.05" type="plane" material="groundplane" />
    <body name="base_unit">
      <geom mesh="base_unit" class="visual" />
      <geom mesh="base_unit" class="collision" />
      <body name="link1" pos="0 0 0.1715">
        <inertial pos="-0.000110636 -0.00547113 -0.0158977" quat="0.98558 0.168758 -0.00294757 0.0120358" mass="2.06488" diaginertia="0.00303337 0.00279081 0.00221937" />
        <joint name="Joint1" class="Joint1" />
        <geom mesh="link1" class="visual" />
        <geom mesh="link1" class="collision" />
        <body name="link2" pos="0 -0.1215 0">
          <inertial pos="1.14054e-05 0.0161842 0.103606" quat="0.999988 -0.00477885 -0.000609836 0.00067321" mass="3.67954" diaginertia="0.051732 0.0503576 0.00449718" />
          <joint name="Joint2" class="Joint2" />
          <geom mesh="link2" class="visual" />
          <geom mesh="link2" class="collision" />
          <body name="link3" pos="0 0 0.247">
            <inertial pos="7.81487e-05 0.107185 0.141173" quat="0.999987 0.00500823 0.000469041 -0.00072733" mass="2.38659" diaginertia="0.0226944 0.021922 0.00277422" />
            <joint name="Joint3" class="Joint3" />
            <geom mesh="link3" class="visual" />
            <geom mesh="link3" class="collision" />
            <body name="link4" pos="0 0.1215 0.2195">
              <inertial pos="-0.000133183 -0.107467 0.0190907" quat="0.983636 0.179196 0.00338061 -0.0183488" mass="1.40023" diaginertia="0.00175475 0.00162284 0.00115817" />
              <joint name="Joint4" class="Joint4" />
              <geom mesh="link4" class="visual" />
              <geom mesh="link4" class="collision" />
              <body name="link5" pos="0 -0.113 0">
                <inertial pos="0.000133183 -0.0190907 0.109967" quat="0.822247 0.568825 0.0105841 -0.015365" mass="1.40023" diaginertia="0.00175475 0.00162284 0.00115817" />
                <joint name="Joint5" class="Joint5" />
                <geom mesh="link5" class="visual" />
                <geom mesh="link5" class="collision" />
                <body name="link6" pos="0 0 0.1155">
                  <inertial pos="1.6005e-05 -0.103085 0.00570277" quat="0.456875 0.889528 0.00170634 -0.00130773" mass="0.652774" diaginertia="0.00112656 0.000847594 0.000551829" />
                  <joint name="Joint6" class="Joint6" />
                  <geom mesh="link6" class="visual" />
                  <geom mesh="link6" class="collision" />
                  <geom pos="0 -0.103 0" mesh="flange" class="visual" />
                  <geom pos="0 -0.103 0" mesh="flange" class="collision" />
                  <geom pos="0 -0.109 0" quat="0.500398 0.5 0.5 -0.499602" mesh="base" class="visual" />
                  <geom pos="0 -0.109 0" quat="0.500398 0.5 0.5 -0.499602" mesh="base" class="collision" />
                  <body name="rh_r1" pos="0.00803822 -0.156994 6.40105e-06" quat="0.500398 0.5 0.5 -0.499602">
                    <inertial pos="0 0.034 0.004" mass="0.068" diaginertia="1e-06 1e-06 1e-06" />
                    <joint name="rh_r1" class="Gripper" />
                    <geom mesh="r1" class="visual" />
                    <geom mesh="r1" class="collision" />
                    <body name="rh_r2" pos="0 0.0493634 0.0285">
                      <inertial pos="0 0.006 0.011" mass="0.022" diaginertia="1e-06 1e-06 1e-06" />
                      <joint name="rh_r2" class="Gripper_mimic" />
                      <geom mesh="r2" class="visual" />
                      <geom mesh="r2" class="collision" />
                    </body>
                  </body>
                  <body name="rh_l1" pos="-0.00796177 -0.157006 -6.34017e-06" quat="0.500398 0.5 0.5 -0.499602">
                    <inertial pos="0 -0.034 0.004" mass="0.068" diaginertia="1e-06 1e-06 1e-06" />
                    <joint name="rh_l1" class="Gripper_mimic" />
                    <geom mesh="l1" class="visual" />
                    <geom mesh="l1" class="collision" />
                    <body name="rh_l2" pos="0 -0.0493634 0.0285">
                      <inertial pos="0 -0.006 0.011" mass="0.022" diaginertia="1e-06 1e-06 1e-06" />
                      <joint name="rh_l2" class="Gripper_mimic_pos" />
                      <geom mesh="l2" class="visual" />
                      <geom mesh="l2" class="collision" />
                    </body>
                  </body>
                  <body name="tip" pos="0 -0.315 0">
                    <inertial pos="0 0.055 0" mass="0.015" diaginertia="1e-5 1e-5 1e-5" />
                    <geom name="tip_mount" type="capsule" fromto="0 0.125 0 0 0.095 0" size="0.012" material="tip_dark" contype="0" conaffinity="0" density="0" />
                    <geom name="tip_shaft" type="capsule" fromto="0 0.105 0 0 0.000 0" size="0.004" material="tip_metal" contype="0" conaffinity="0" condim="3" friction="1 0.005 0.0001" density="0" />
                    <site name="tip_site" pos="0 0 0" size="0.007" rgba="1 0.1 0.1 1" />
                  </body>
                </body>
              </body>
            </body>
          </body>
        </body>
      </body>
    </body>
    <body name="maze" pos="0.3400 0.0000 0.0000">
      <geom name="maze_floor_flat_right" type="box" pos="0.0000 -0.1200 0.0040" size="0.2400 0.1200 0.0040" material="maze_floor" contype="1" conaffinity="1" friction="1 0.005 0.0001" />
      <geom name="maze_floor_folded_left_30deg" type="box" pos="0.0000 0.1059 0.0645" quat="0.9659258263 0.2588190451 0 0" size="0.2400 0.1200 0.0040" material="maze_floor" contype="1" conaffinity="1" friction="1 0.005 0.0001" />
      <geom name="maze_fold_hinge_axis" type="cylinder" pos="0.0000 0.0000 0.0080" quat="0.7071067812 0 0.7071067812 0" size="0.0040 0.2450" material="tip_metal" contype="0" conaffinity="0" />
      <site name="maze_origin_ll" pos="-0.2400 -0.2400 0.0130" size="0.0060" rgba="0.1 0.1 1.0 1" />
      <site name="maze_entrance" pos="-0.1800 -0.2200 0.0130" size="0.0060" rgba="0.1 0.6 1.0 1" />
      <site name="maze_start" pos="-0.1000 -0.1800 0.0130" size="0.0080" rgba="0.1 0.9 0.1 1" />
      <site name="maze_goal" pos="-0.1000 -0.1300 0.0130" size="0.0080" rgba="0.9 0.1 0.1 1" />
      <geom name="maze_start_marker" type="sphere" pos="-0.1000 -0.1800 0.0180" size="0.0090" rgba="0.0 1.0 0.0 1" contype="0" conaffinity="0" />
      <geom name="maze_goal_marker" type="sphere" pos="-0.1000 -0.1300 0.0180" size="0.0090" rgba="1.0 0.0 0.0 1" contype="0" conaffinity="0" />
      <site name="maze_exit" pos="0.1800 0.1880 0.1223" size="0.0060" rgba="1.0 0.6 0.1 1" />
      <site name="maze_fold_hinge_center" pos="0.0000 0.0000 0.0080" size="0.0060" rgba="0.8 0.8 0.1 1" />
    <geom name="maze_cube_r00_c00" type="box" pos="-0.2200 -0.2200 0.0280" size="0.0200 0.0200 0.0200" material="maze_wall" contype="1" conaffinity="1" friction="1 0.005 0.0001" /><geom name="maze_cube_r00_c02" type="box" pos="-0.1400 -0.2200 0.0280" size="0.0200 0.0200 0.0200" material="maze_wall" contype="1" conaffinity="1" friction="1 0.005 0.0001" /><geom name="maze_cube_r00_c03" type="box" pos="-0.1000 -0.2200 0.0280" size="0.0200 0.0200 0.0200" material="maze_wall" contype="1" conaffinity="1" friction="1 0.005 0.0001" /><geom name="maze_cube_r00_c04" type="box" pos="-0.0600 -0.2200 0.0280" size="0.0200 0.0200 0.0200" material="maze_wall" contype="1" conaffinity="1" friction="1 0.005 0.0001" /><geom name="maze_cube_r00_c05" type="box" pos="-0.0200 -0.2200 0.0280" size="0.0200 0.0200 0.0200" material="maze_wall" contype="1" conaffinity="1" friction="1 0.005 0.0001" /><geom name="maze_cube_r00_c06" type="box" pos="0.0200 -0.2200 0.0280" size="0.0200 0.0200 0.0200" material="maze_wall" contype="1" conaffinity="1" friction="1 0.005 0.0001" /><geom name="maze_cube_r00_c07" type="box" pos="0.0600 -0.2200 0.0280" size="0.0200 0.0200 0.0200" material="maze_wall" contype="1" conaffinity="1" friction="1 0.005 0.0001" /><geom name="maze_cube_r00_c08" type="box" pos="0.1000 -0.2200 0.0280" size="0.0200 0.0200 0.0200" material="maze_wall" contype="1" conaffinity="1" friction="1 0.005 0.0001" /><geom name="maze_cube_r00_c09" type="box" pos="0.1400 -0.2200 0.0280" size="0.0200 0.0200 0.0200" material="maze_wall" contype="1" conaffinity="1" friction="1 0.005 0.0001" /><geom name="maze_cube_r00_c10" type="box" pos="0.1800 -0.2200 0.0280" size="0.0200 0.0200 0.0200" material="maze_wall" contype="1" conaffinity="1" friction="1 0.005 0.0001" /><geom name="maze_cube_r00_c11" type="box" pos="0.2200 -0.2200 0.0280" size="0.0200 0.0200 0.0200" material="maze_wall" contype="1" conaffinity="1" friction="1 0.005 0.0001" /><geom name="maze_cube_r01_c00" type="box" pos="-0.2200 -0.1800 0.0280" size="0.0200 0.0200 0.0200" material="maze_wall" contype="1" conaffinity="1" friction="1 0.005 0.0001" /><geom name="maze_cube_r01_c02" type="box" pos="-0.1400 -0.1800 0.0280" size="0.0200 0.0200 0.0200" material="maze_wall" contype="1" conaffinity="1" friction="1 0.005 0.0001" /><geom name="maze_cube_r01_c08" type="box" pos="0.1000 -0.1800 0.0280" size="0.0200 0.0200 0.0200" material="maze_wall" contype="1" conaffinity="1" friction="1 0.005 0.0001" /><geom name="maze_cube_r01_c10" type="box" pos="0.1800 -0.1800 0.0280" size="0.0200 0.0200 0.0200" material="maze_wall" contype="1" conaffinity="1" friction="1 0.005 0.0001" /><geom name="maze_cube_r01_c11" type="box" pos="0.2200 -0.1800 0.0280" size="0.0200 0.0200 0.0200" material="maze_wall" contype="1" conaffinity="1" friction="1 0.005 0.0001" /><geom name="maze_cube_r02_c00" type="box" pos="-0.2200 -0.1400 0.0280" size="0.0200 0.0200 0.0200" material="maze_wall" contype="1" conaffinity="1" friction="1 0.005 0.0001" /><geom name="maze_cube_r02_c02" type="box" pos="-0.1400 -0.1400 0.0280" size="0.0200 0.0200 0.0200" material="maze_wall" contype="1" conaffinity="1" friction="1 0.005 0.0001" /><geom name="maze_cube_r02_c04" type="box" pos="-0.0600 -0.1400 0.0280" size="0.0200 0.0200 0.0200" material="maze_wall" contype="1" conaffinity="1" friction="1 0.005 0.0001" /><geom name="maze_cube_r02_c05" type="box" pos="-0.0200 -0.1400 0.0280" size="0.0200 0.0200 0.0200" material="maze_wall" contype="1" conaffinity="1" friction="1 0.005 0.0001" /><geom name="maze_cube_r02_c06" type="box" pos="0.0200 -0.1400 0.0280" size="0.0200 0.0200 0.0200" material="maze_wall" contype="1" conaffinity="1" friction="1 0.005 0.0001" /><geom name="maze_cube_r02_c08" type="box" pos="0.1000 -0.1400 0.0280" size="0.0200 0.0200 0.0200" material="maze_wall" contype="1" conaffinity="1" friction="1 0.005 0.0001" /><geom name="maze_cube_r02_c10" type="box" pos="0.1800 -0.1400 0.0280" size="0.0200 0.0200 0.0200" material="maze_wall" contype="1" conaffinity="1" friction="1 0.005 0.0001" /><geom name="maze_cube_r02_c11" type="box" pos="0.2200 -0.1400 0.0280" size="0.0200 0.0200 0.0200" material="maze_wall" contype="1" conaffinity="1" friction="1 0.005 0.0001" /><geom name="maze_cube_r03_c00" type="box" pos="-0.2200 -0.1000 0.0280" size="0.0200 0.0200 0.0200" material="maze_wall" contype="1" conaffinity="1" friction="1 0.005 0.0001" /><geom name="maze_cube_r03_c02" type="box" pos="-0.1400 -0.1000 0.0280" size="0.0200 0.0200 0.0200" material="maze_wall" contype="1" conaffinity="1" friction="1 0.005 0.0001" /><geom name="maze_cube_r03_c06" type="box" pos="0.0200 -0.1000 0.0280" size="0.0200 0.0200 0.0200" material="maze_wall" contype="1" conaffinity="1" friction="1 0.005 0.0001" /><geom name="maze_cube_r03_c10" type="box" pos="0.1800 -0.1000 0.0280" size="0.0200 0.0200 0.0200" material="maze_wall" contype="1" conaffinity="1" friction="1 0.005 0.0001" /><geom name="maze_cube_r03_c11" type="box" pos="0.2200 -0.1000 0.0280" size="0.0200 0.0200 0.0200" material="maze_wall" contype="1" conaffinity="1" friction="1 0.005 0.0001" /><geom name="maze_cube_r04_c00" type="box" pos="-0.2200 -0.0600 0.0280" size="0.0200 0.0200 0.0200" material="maze_wall" contype="1" conaffinity="1" friction="1 0.005 0.0001" /><geom name="maze_cube_r04_c02" type="box" pos="-0.1400 -0.0600 0.0280" size="0.0200 0.0200 0.0200" material="maze_wall" contype="1" conaffinity="1" friction="1 0.005 0.0001" /><geom name="maze_cube_r04_c03" type="box" pos="-0.1000 -0.0600 0.0280" size="0.0200 0.0200 0.0200" material="maze_wall" contype="1" conaffinity="1" friction="1 0.005 0.0001" /><geom name="maze_cube_r04_c04" type="box" pos="-0.0600 -0.0600 0.0280" size="0.0200 0.0200 0.0200" material="maze_wall" contype="1" conaffinity="1" friction="1 0.005 0.0001" /><geom name="maze_cube_r04_c06" type="box" pos="0.0200 -0.0600 0.0280" size="0.0200 0.0200 0.0200" material="maze_wall" contype="1" conaffinity="1" friction="1 0.005 0.0001" /><geom name="maze_cube_r04_c07" type="box" pos="0.0600 -0.0600 0.0280" size="0.0200 0.0200 0.0200" material="maze_wall" contype="1" conaffinity="1" friction="1 0.005 0.0001" /><geom name="maze_cube_r04_c08" type="box" pos="0.1000 -0.0600 0.0280" size="0.0200 0.0200 0.0200" material="maze_wall" contype="1" conaffinity="1" friction="1 0.005 0.0001" /><geom name="maze_cube_r04_c10" type="box" pos="0.1800 -0.0600 0.0280" size="0.0200 0.0200 0.0200" material="maze_wall" contype="1" conaffinity="1" friction="1 0.005 0.0001" /><geom name="maze_cube_r04_c11" type="box" pos="0.2200 -0.0600 0.0280" size="0.0200 0.0200 0.0200" material="maze_wall" contype="1" conaffinity="1" friction="1 0.005 0.0001" /><geom name="maze_cube_r05_c00" type="box" pos="-0.2200 -0.0200 0.0280" size="0.0200 0.0200 0.0200" material="maze_wall" contype="1" conaffinity="1" friction="1 0.005 0.0001" /><geom name="maze_cube_r05_c06" type="box" pos="0.0200 -0.0200 0.0280" size="0.0200 0.0200 0.0200" material="maze_wall" contype="1" conaffinity="1" friction="1 0.005 0.0001" /><geom name="maze_cube_r05_c08" type="box" pos="0.1000 -0.0200 0.0280" size="0.0200 0.0200 0.0200" material="maze_wall" contype="1" conaffinity="1" friction="1 0.005 0.0001" /><geom name="maze_cube_r05_c10" type="box" pos="0.1800 -0.0200 0.0280" size="0.0200 0.0200 0.0200" material="maze_wall" contype="1" conaffinity="1" friction="1 0.005 0.0001" /><geom name="maze_cube_r05_c11" type="box" pos="0.2200 -0.0200 0.0280" size="0.0200 0.0200 0.0200" material="maze_wall" contype="1" conaffinity="1" friction="1 0.005 0.0001" /><geom name="maze_cube_r06_c00" type="box" pos="-0.2200 0.0073 0.0353" quat="0.9659258263 0.2588190451 0 0" size="0.0200 0.0200 0.0200" material="maze_wall" contype="1" conaffinity="1" friction="1 0.005 0.0001" /><geom name="maze_cube_r06_c01" type="box" pos="-0.1800 0.0073 0.0353" quat="0.9659258263 0.2588190451 0 0" size="0.0200 0.0200 0.0200" material="maze_wall" contype="1" conaffinity="1" friction="1 0.005 0.0001" /><geom name="maze_cube_r06_c02" type="box" pos="-0.1400 0.0073 0.0353" quat="0.9659258263 0.2588190451 0 0" size="0.0200 0.0200 0.0200" material="maze_wall" contype="1" conaffinity="1" friction="1 0.005 0.0001" /><geom name="maze_cube_r06_c03" type="box" pos="-0.1000 0.0073 0.0353" quat="0.9659258263 0.2588190451 0 0" size="0.0200 0.0200 0.0200" material="maze_wall" contype="1" conaffinity="1" friction="1 0.005 0.0001" /><geom name="maze_cube_r06_c04" type="box" pos="-0.0600 0.0073 0.0353" quat="0.9659258263 0.2588190451 0 0" size="0.0200 0.0200 0.0200" material="maze_wall" contype="1" conaffinity="1" friction="1 0.005 0.0001" /><geom name="maze_cube_r06_c05" type="box" pos="-0.0200 0.0073 0.0353" quat="0.9659258263 0.2588190451 0 0" size="0.0200 0.0200 0.0200" material="maze_wall" contype="1" conaffinity="1" friction="1 0.005 0.0001" /><geom name="maze_cube_r06_c06" type="box" pos="0.0200 0.0073 0.0353" quat="0.9659258263 0.2588190451 0 0" size="0.0200 0.0200 0.0200" material="maze_wall" contype="1" conaffinity="1" friction="1 0.005 0.0001" /><geom name="maze_cube_r06_c08" type="box" pos="0.1000 0.0073 0.0353" quat="0.9659258263 0.2588190451 0 0" size="0.0200 0.0200 0.0200" material="maze_wall" contype="1" conaffinity="1" friction="1 0.005 0.0001" /><geom name="maze_cube_r06_c10" type="box" pos="0.1800 0.0073 0.0353" quat="0.9659258263 0.2588190451 0 0" size="0.0200 0.0200 0.0200" material="maze_wall" contype="1" conaffinity="1" friction="1 0.005 0.0001" /><geom name="maze_cube_r06_c11" type="box" pos="0.2200 0.0073 0.0353" quat="0.9659258263 0.2588190451 0 0" size="0.0200 0.0200 0.0200" material="maze_wall" contype="1" conaffinity="1" friction="1 0.005 0.0001" /><geom name="maze_cube_r07_c00" type="box" pos="-0.2200 0.0419 0.0553" quat="0.9659258263 0.2588190451 0 0" size="0.0200 0.0200 0.0200" material="maze_wall" contype="1" conaffinity="1" friction="1 0.005 0.0001" /><geom name="maze_cube_r07_c02" type="box" pos="-0.1400 0.0419 0.0553" quat="0.9659258263 0.2588190451 0 0" size="0.0200 0.0200 0.0200" material="maze_wall" contype="1" conaffinity="1" friction="1 0.005 0.0001" /><geom name="maze_cube_r07_c10" type="box" pos="0.1800 0.0419 0.0553" quat="0.9659258263 0.2588190451 0 0" size="0.0200 0.0200 0.0200" material="maze_wall" contype="1" conaffinity="1" friction="1 0.005 0.0001" /><geom name="maze_cube_r07_c11" type="box" pos="0.2200 0.0419 0.0553" quat="0.9659258263 0.2588190451 0 0" size="0.0200 0.0200 0.0200" material="maze_wall" contype="1" conaffinity="1" friction="1 0.005 0.0001" /><geom name="maze_cube_r08_c00" type="box" pos="-0.2200 0.0766 0.0753" quat="0.9659258263 0.2588190451 0 0" size="0.0200 0.0200 0.0200" material="maze_wall" contype="1" conaffinity="1" friction="1 0.005 0.0001" /><geom name="maze_cube_r08_c02" type="box" pos="-0.1400 0.0766 0.0753" quat="0.9659258263 0.2588190451 0 0" size="0.0200 0.0200 0.0200" material="maze_wall" contype="1" conaffinity="1" friction="1 0.005 0.0001" /><geom name="maze_cube_r08_c04" type="box" pos="-0.0600 0.0766 0.0753" quat="0.9659258263 0.2588190451 0 0" size="0.0200 0.0200 0.0200" material="maze_wall" contype="1" conaffinity="1" friction="1 0.005 0.0001" /><geom name="maze_cube_r08_c05" type="box" pos="-0.0200 0.0766 0.0753" quat="0.9659258263 0.2588190451 0 0" size="0.0200 0.0200 0.0200" material="maze_wall" contype="1" conaffinity="1" friction="1 0.005 0.0001" /><geom name="maze_cube_r08_c06" type="box" pos="0.0200 0.0766 0.0753" quat="0.9659258263 0.2588190451 0 0" size="0.0200 0.0200 0.0200" material="maze_wall" contype="1" conaffinity="1" friction="1 0.005 0.0001" /><geom name="maze_cube_r08_c07" type="box" pos="0.0600 0.0766 0.0753" quat="0.9659258263 0.2588190451 0 0" size="0.0200 0.0200 0.0200" material="maze_wall" contype="1" conaffinity="1" friction="1 0.005 0.0001" /><geom name="maze_cube_r08_c08" type="box" pos="0.1000 0.0766 0.0753" quat="0.9659258263 0.2588190451 0 0" size="0.0200 0.0200 0.0200" material="maze_wall" contype="1" conaffinity="1" friction="1 0.005 0.0001" /><geom name="maze_cube_r08_c09" type="box" pos="0.1400 0.0766 0.0753" quat="0.9659258263 0.2588190451 0 0" size="0.0200 0.0200 0.0200" material="maze_wall" contype="1" conaffinity="1" friction="1 0.005 0.0001" /><geom name="maze_cube_r08_c10" type="box" pos="0.1800 0.0766 0.0753" quat="0.9659258263 0.2588190451 0 0" size="0.0200 0.0200 0.0200" material="maze_wall" contype="1" conaffinity="1" friction="1 0.005 0.0001" /><geom name="maze_cube_r08_c11" type="box" pos="0.2200 0.0766 0.0753" quat="0.9659258263 0.2588190451 0 0" size="0.0200 0.0200 0.0200" material="maze_wall" contype="1" conaffinity="1" friction="1 0.005 0.0001" /><geom name="maze_cube_r09_c00" type="box" pos="-0.2200 0.1112 0.0953" quat="0.9659258263 0.2588190451 0 0" size="0.0200 0.0200 0.0200" material="maze_wall" contype="1" conaffinity="1" friction="1 0.005 0.0001" /><geom name="maze_cube_r09_c10" type="box" pos="0.1800 0.1112 0.0953" quat="0.9659258263 0.2588190451 0 0" size="0.0200 0.0200 0.0200" material="maze_wall" contype="1" conaffinity="1" friction="1 0.005 0.0001" /><geom name="maze_cube_r09_c11" type="box" pos="0.2200 0.1112 0.0953" quat="0.9659258263 0.2588190451 0 0" size="0.0200 0.0200 0.0200" material="maze_wall" contype="1" conaffinity="1" friction="1 0.005 0.0001" /><geom name="maze_cube_r10_c00" type="box" pos="-0.2200 0.1459 0.1153" quat="0.9659258263 0.2588190451 0 0" size="0.0200 0.0200 0.0200" material="maze_wall" contype="1" conaffinity="1" friction="1 0.005 0.0001" /><geom name="maze_cube_r10_c01" type="box" pos="-0.1800 0.1459 0.1153" quat="0.9659258263 0.2588190451 0 0" size="0.0200 0.0200 0.0200" material="maze_wall" contype="1" conaffinity="1" friction="1 0.005 0.0001" /><geom name="maze_cube_r10_c02" type="box" pos="-0.1400 0.1459 0.1153" quat="0.9659258263 0.2588190451 0 0" size="0.0200 0.0200 0.0200" material="maze_wall" contype="1" conaffinity="1" friction="1 0.005 0.0001" /><geom name="maze_cube_r10_c03" type="box" pos="-0.1000 0.1459 0.1153" quat="0.9659258263 0.2588190451 0 0" size="0.0200 0.0200 0.0200" material="maze_wall" contype="1" conaffinity="1" friction="1 0.005 0.0001" /><geom name="maze_cube_r10_c04" type="box" pos="-0.0600 0.1459 0.1153" quat="0.9659258263 0.2588190451 0 0" size="0.0200 0.0200 0.0200" material="maze_wall" contype="1" conaffinity="1" friction="1 0.005 0.0001" /><geom name="maze_cube_r10_c05" type="box" pos="-0.0200 0.1459 0.1153" quat="0.9659258263 0.2588190451 0 0" size="0.0200 0.0200 0.0200" material="maze_wall" contype="1" conaffinity="1" friction="1 0.005 0.0001" /><geom name="maze_cube_r10_c06" type="box" pos="0.0200 0.1459 0.1153" quat="0.9659258263 0.2588190451 0 0" size="0.0200 0.0200 0.0200" material="maze_wall" contype="1" conaffinity="1" friction="1 0.005 0.0001" /><geom name="maze_cube_r10_c07" type="box" pos="0.0600 0.1459 0.1153" quat="0.9659258263 0.2588190451 0 0" size="0.0200 0.0200 0.0200" material="maze_wall" contype="1" conaffinity="1" friction="1 0.005 0.0001" /><geom name="maze_cube_r10_c08" type="box" pos="0.1000 0.1459 0.1153" quat="0.9659258263 0.2588190451 0 0" size="0.0200 0.0200 0.0200" material="maze_wall" contype="1" conaffinity="1" friction="1 0.005 0.0001" /><geom name="maze_cube_r10_c11" type="box" pos="0.2200 0.1459 0.1153" quat="0.9659258263 0.2588190451 0 0" size="0.0200 0.0200 0.0200" material="maze_wall" contype="1" conaffinity="1" friction="1 0.005 0.0001" /><geom name="maze_cube_r11_c00" type="box" pos="-0.2200 0.1805 0.1353" quat="0.9659258263 0.2588190451 0 0" size="0.0200 0.0200 0.0200" material="maze_wall" contype="1" conaffinity="1" friction="1 0.005 0.0001" /><geom name="maze_cube_r11_c01" type="box" pos="-0.1800 0.1805 0.1353" quat="0.9659258263 0.2588190451 0 0" size="0.0200 0.0200 0.0200" material="maze_wall" contype="1" conaffinity="1" friction="1 0.005 0.0001" /><geom name="maze_cube_r11_c02" type="box" pos="-0.1400 0.1805 0.1353" quat="0.9659258263 0.2588190451 0 0" size="0.0200 0.0200 0.0200" material="maze_wall" contype="1" conaffinity="1" friction="1 0.005 0.0001" /><geom name="maze_cube_r11_c03" type="box" pos="-0.1000 0.1805 0.1353" quat="0.9659258263 0.2588190451 0 0" size="0.0200 0.0200 0.0200" material="maze_wall" contype="1" conaffinity="1" friction="1 0.005 0.0001" /><geom name="maze_cube_r11_c04" type="box" pos="-0.0600 0.1805 0.1353" quat="0.9659258263 0.2588190451 0 0" size="0.0200 0.0200 0.0200" material="maze_wall" contype="1" conaffinity="1" friction="1 0.005 0.0001" /><geom name="maze_cube_r11_c05" type="box" pos="-0.0200 0.1805 0.1353" quat="0.9659258263 0.2588190451 0 0" size="0.0200 0.0200 0.0200" material="maze_wall" contype="1" conaffinity="1" friction="1 0.005 0.0001" /><geom name="maze_cube_r11_c06" type="box" pos="0.0200 0.1805 0.1353" quat="0.9659258263 0.2588190451 0 0" size="0.0200 0.0200 0.0200" material="maze_wall" contype="1" conaffinity="1" friction="1 0.005 0.0001" /><geom name="maze_cube_r11_c07" type="box" pos="0.0600 0.1805 0.1353" quat="0.9659258263 0.2588190451 0 0" size="0.0200 0.0200 0.0200" material="maze_wall" contype="1" conaffinity="1" friction="1 0.005 0.0001" /><geom name="maze_cube_r11_c08" type="box" pos="0.1000 0.1805 0.1353" quat="0.9659258263 0.2588190451 0 0" size="0.0200 0.0200 0.0200" material="maze_wall" contype="1" conaffinity="1" friction="1 0.005 0.0001" /><geom name="maze_cube_r11_c09" type="box" pos="0.1400 0.1805 0.1353" quat="0.9659258263 0.2588190451 0 0" size="0.0200 0.0200 0.0200" material="maze_wall" contype="1" conaffinity="1" friction="1 0.005 0.0001" /><geom name="maze_cube_r11_c11" type="box" pos="0.2200 0.1805 0.1353" quat="0.9659258263 0.2588190451 0 0" size="0.0200 0.0200 0.0200" material="maze_wall" contype="1" conaffinity="1" friction="1 0.005 0.0001" /><geom name="planned_path_seg_000" type="capsule" fromto="-0.18000 -0.18000 0.01800 -0.18000 -0.17191 0.01800" size="0.0022" material="planned_path" contype="0" conaffinity="0" /><geom name="planned_path_seg_001" type="capsule" fromto="-0.18000 -0.17191 0.01800 -0.18000 -0.16382 0.01800" size="0.0022" material="planned_path" contype="0" conaffinity="0" /><geom name="planned_path_seg_002" type="capsule" fromto="-0.18000 -0.16382 0.01800 -0.18000 -0.15574 0.01800" size="0.0022" material="planned_path" contype="0" conaffinity="0" /><geom name="planned_path_seg_003" type="capsule" fromto="-0.18000 -0.15574 0.01800 -0.18000 -0.14765 0.01800" size="0.0022" material="planned_path" contype="0" conaffinity="0" /><geom name="planned_path_seg_004" type="capsule" fromto="-0.18000 -0.14765 0.01800 -0.18000 -0.13956 0.01800" size="0.0022" material="planned_path" contype="0" conaffinity="0" /><geom name="planned_path_seg_005" type="capsule" fromto="-0.18000 -0.13956 0.01800 -0.18000 -0.13147 0.01800" size="0.0022" material="planned_path" contype="0" conaffinity="0" /><geom name="planned_path_seg_006" type="capsule" fromto="-0.18000 -0.13147 0.01800 -0.18000 -0.12338 0.01800" size="0.0022" material="planned_path" contype="0" conaffinity="0" /><geom name="planned_path_seg_007" type="capsule" fromto="-0.18000 -0.12338 0.01800 -0.18000 -0.11530 0.01800" size="0.0022" material="planned_path" contype="0" conaffinity="0" /><geom name="planned_path_seg_008" type="capsule" fromto="-0.18000 -0.11530 0.01800 -0.18000 -0.10721 0.01800" size="0.0022" material="planned_path" contype="0" conaffinity="0" /><geom name="planned_path_seg_009" type="capsule" fromto="-0.18000 -0.10721 0.01800 -0.18000 -0.09912 0.01800" size="0.0022" material="planned_path" contype="0" conaffinity="0" /><geom name="planned_path_seg_010" type="capsule" fromto="-0.18000 -0.09912 0.01800 -0.18000 -0.09103 0.01800" size="0.0022" material="planned_path" contype="0" conaffinity="0" /><geom name="planned_path_seg_011" type="capsule" fromto="-0.18000 -0.09103 0.01800 -0.18000 -0.08294 0.01800" size="0.0022" material="planned_path" contype="0" conaffinity="0" /><geom name="planned_path_seg_012" type="capsule" fromto="-0.18000 -0.08294 0.01800 -0.18000 -0.07486 0.01800" size="0.0022" material="planned_path" contype="0" conaffinity="0" /><geom name="planned_path_seg_013" type="capsule" fromto="-0.18000 -0.07486 0.01800 -0.18000 -0.06677 0.01800" size="0.0022" material="planned_path" contype="0" conaffinity="0" /><geom name="planned_path_seg_014" type="capsule" fromto="-0.18000 -0.06677 0.01800 -0.18000 -0.05868 0.01800" size="0.0022" material="planned_path" contype="0" conaffinity="0" /><geom name="planned_path_seg_015" type="capsule" fromto="-0.18000 -0.05868 0.01800 -0.18000 -0.05059 0.01800" size="0.0022" material="planned_path" contype="0" conaffinity="0" /><geom name="planned_path_seg_016" type="capsule" fromto="-0.18000 -0.05059 0.01800 -0.18000 -0.04250 0.01800" size="0.0022" material="planned_path" contype="0" conaffinity="0" /><geom name="planned_path_seg_017" type="capsule" fromto="-0.18000 -0.04250 0.01800 -0.18000 -0.03442 0.01800" size="0.0022" material="planned_path" contype="0" conaffinity="0" /><geom name="planned_path_seg_018" type="capsule" fromto="-0.18000 -0.03442 0.01800 -0.17836 -0.02660 0.01800" size="0.0022" material="planned_path" contype="0" conaffinity="0" /><geom name="planned_path_seg_019" type="capsule" fromto="-0.17836 -0.02660 0.01800 -0.17267 -0.02120 0.01800" size="0.0022" material="planned_path" contype="0" conaffinity="0" /><geom name="planned_path_seg_020" type="capsule" fromto="-0.17267 -0.02120 0.01800 -0.16473 -0.02000 0.01800" size="0.0022" material="planned_path" contype="0" conaffinity="0" /><geom name="planned_path_seg_021" type="capsule" fromto="-0.16473 -0.02000 0.01800 -0.15664 -0.02000 0.01800" size="0.0022" material="planned_path" contype="0" conaffinity="0" /><geom name="planned_path_seg_022" type="capsule" fromto="-0.15664 -0.02000 0.01800 -0.14855 -0.02000 0.01800" size="0.0022" material="planned_path" contype="0" conaffinity="0" /><geom name="planned_path_seg_023" type="capsule" fromto="-0.14855 -0.02000 0.01800 -0.14047 -0.02000 0.01800" size="0.0022" material="planned_path" contype="0" conaffinity="0" /><geom name="planned_path_seg_024" type="capsule" fromto="-0.14047 -0.02000 0.01800 -0.13238 -0.02000 0.01800" size="0.0022" material="planned_path" contype="0" conaffinity="0" /><geom name="planned_path_seg_025" type="capsule" fromto="-0.13238 -0.02000 0.01800 -0.12429 -0.02000 0.01800" size="0.0022" material="planned_path" contype="0" conaffinity="0" /><geom name="planned_path_seg_026" type="capsule" fromto="-0.12429 -0.02000 0.01800 -0.11620 -0.02000 0.01800" size="0.0022" material="planned_path" contype="0" conaffinity="0" /><geom name="planned_path_seg_027" type="capsule" fromto="-0.11620 -0.02000 0.01800 -0.10811 -0.02000 0.01800" size="0.0022" material="planned_path" contype="0" conaffinity="0" /><geom name="planned_path_seg_028" type="capsule" fromto="-0.10811 -0.02000 0.01800 -0.10003 -0.02000 0.01800" size="0.0022" material="planned_path" contype="0" conaffinity="0" /><geom name="planned_path_seg_029" type="capsule" fromto="-0.10003 -0.02000 0.01800 -0.09194 -0.02000 0.01800" size="0.0022" material="planned_path" contype="0" conaffinity="0" /><geom name="planned_path_seg_030" type="capsule" fromto="-0.09194 -0.02000 0.01800 -0.08385 -0.02000 0.01800" size="0.0022" material="planned_path" contype="0" conaffinity="0" /><geom name="planned_path_seg_031" type="capsule" fromto="-0.08385 -0.02000 0.01800 -0.07576 -0.02000 0.01800" size="0.0022" material="planned_path" contype="0" conaffinity="0" /><geom name="planned_path_seg_032" type="capsule" fromto="-0.07576 -0.02000 0.01800 -0.06767 -0.02000 0.01800" size="0.0022" material="planned_path" contype="0" conaffinity="0" /><geom name="planned_path_seg_033" type="capsule" fromto="-0.06767 -0.02000 0.01800 -0.05959 -0.02000 0.01800" size="0.0022" material="planned_path" contype="0" conaffinity="0" /><geom name="planned_path_seg_034" type="capsule" fromto="-0.05959 -0.02000 0.01800 -0.05150 -0.02000 0.01800" size="0.0022" material="planned_path" contype="0" conaffinity="0" /><geom name="planned_path_seg_035" type="capsule" fromto="-0.05150 -0.02000 0.01800 -0.04341 -0.02000 0.01800" size="0.0022" material="planned_path" contype="0" conaffinity="0" /><geom name="planned_path_seg_036" type="capsule" fromto="-0.04341 -0.02000 0.01800 -0.03532 -0.02000 0.01800" size="0.0022" material="planned_path" contype="0" conaffinity="0" /><geom name="planned_path_seg_037" type="capsule" fromto="-0.03532 -0.02000 0.01800 -0.02738 -0.02117 0.01800" size="0.0022" material="planned_path" contype="0" conaffinity="0" /><geom name="planned_path_seg_038" type="capsule" fromto="-0.02738 -0.02117 0.01800 -0.02167 -0.02656 0.01800" size="0.0022" material="planned_path" contype="0" conaffinity="0" /><geom name="planned_path_seg_039" type="capsule" fromto="-0.02167 -0.02656 0.01800 -0.02000 -0.03436 0.01800" size="0.0022" material="planned_path" contype="0" conaffinity="0" /><geom name="planned_path_seg_040" type="capsule" fromto="-0.02000 -0.03436 0.01800 -0.02000 -0.04245 0.01800" size="0.0022" material="planned_path" contype="0" conaffinity="0" /><geom name="planned_path_seg_041" type="capsule" fromto="-0.02000 -0.04245 0.01800 -0.02000 -0.05054 0.01800" size="0.0022" material="planned_path" contype="0" conaffinity="0" /><geom name="planned_path_seg_042" type="capsule" fromto="-0.02000 -0.05054 0.01800 -0.02000 -0.05863 0.01800" size="0.0022" material="planned_path" contype="0" conaffinity="0" /><geom name="planned_path_seg_043" type="capsule" fromto="-0.02000 -0.05863 0.01800 -0.02000 -0.06672 0.01800" size="0.0022" material="planned_path" contype="0" conaffinity="0" /><geom name="planned_path_seg_044" type="capsule" fromto="-0.02000 -0.06672 0.01800 -0.02000 -0.07480 0.01800" size="0.0022" material="planned_path" contype="0" conaffinity="0" /><geom name="planned_path_seg_045" type="capsule" fromto="-0.02000 -0.07480 0.01800 -0.02000 -0.08289 0.01800" size="0.0022" material="planned_path" contype="0" conaffinity="0" /><geom name="planned_path_seg_046" type="capsule" fromto="-0.02000 -0.08289 0.01800 -0.02070 -0.09093 0.01800" size="0.0022" material="planned_path" contype="0" conaffinity="0" /><geom name="planned_path_seg_047" type="capsule" fromto="-0.02070 -0.09093 0.01800 -0.02503 -0.09742 0.01800" size="0.0022" material="planned_path" contype="0" conaffinity="0" /><geom name="planned_path_seg_048" type="capsule" fromto="-0.02503 -0.09742 0.01800 -0.03259 -0.09980 0.01800" size="0.0022" material="planned_path" contype="0" conaffinity="0" /><geom name="planned_path_seg_049" type="capsule" fromto="-0.03259 -0.09980 0.01800 -0.04067 -0.10000 0.01800" size="0.0022" material="planned_path" contype="0" conaffinity="0" /><geom name="planned_path_seg_050" type="capsule" fromto="-0.04067 -0.10000 0.01800 -0.04875 -0.10000 0.01800" size="0.0022" material="planned_path" contype="0" conaffinity="0" /><geom name="planned_path_seg_051" type="capsule" fromto="-0.04875 -0.10000 0.01800 -0.05684 -0.10000 0.01800" size="0.0022" material="planned_path" contype="0" conaffinity="0" /><geom name="planned_path_seg_052" type="capsule" fromto="-0.05684 -0.10000 0.01800 -0.06493 -0.10000 0.01800" size="0.0022" material="planned_path" contype="0" conaffinity="0" /><geom name="planned_path_seg_053" type="capsule" fromto="-0.06493 -0.10000 0.01800 -0.07302 -0.10000 0.01800" size="0.0022" material="planned_path" contype="0" conaffinity="0" /><geom name="planned_path_seg_054" type="capsule" fromto="-0.07302 -0.10000 0.01800 -0.08111 -0.10000 0.01800" size="0.0022" material="planned_path" contype="0" conaffinity="0" /><geom name="planned_path_seg_055" type="capsule" fromto="-0.08111 -0.10000 0.01800 -0.08916 -0.10045 0.01800" size="0.0022" material="planned_path" contype="0" conaffinity="0" /><geom name="planned_path_seg_056" type="capsule" fromto="-0.08916 -0.10045 0.01800 -0.09649 -0.10350 0.01800" size="0.0022" material="planned_path" contype="0" conaffinity="0" /><geom name="planned_path_seg_057" type="capsule" fromto="-0.09649 -0.10350 0.01800 -0.09955 -0.11082 0.01800" size="0.0022" material="planned_path" contype="0" conaffinity="0" /><geom name="planned_path_seg_058" type="capsule" fromto="-0.09955 -0.11082 0.01800 -0.10000 -0.11888 0.01800" size="0.0022" material="planned_path" contype="0" conaffinity="0" /><geom name="planned_path_seg_059" type="capsule" fromto="-0.10000 -0.11888 0.01800 -0.10000 -0.12697 0.01800" size="0.0022" material="planned_path" contype="0" conaffinity="0" /><geom name="planned_path_seg_060" type="capsule" fromto="-0.10000 -0.12697 0.01800 -0.10000 -0.13506 0.01800" size="0.0022" material="planned_path" contype="0" conaffinity="0" /><geom name="planned_path_seg_061" type="capsule" fromto="-0.10000 -0.13506 0.01800 -0.10000 -0.14314 0.01800" size="0.0022" material="planned_path" contype="0" conaffinity="0" /><geom name="planned_path_seg_062" type="capsule" fromto="-0.10000 -0.14314 0.01800 -0.10000 -0.15123 0.01800" size="0.0022" material="planned_path" contype="0" conaffinity="0" /><geom name="planned_path_seg_063" type="capsule" fromto="-0.10000 -0.15123 0.01800 -0.10000 -0.15932 0.01800" size="0.0022" material="planned_path" contype="0" conaffinity="0" /><geom name="planned_path_seg_064" type="capsule" fromto="-0.10000 -0.15932 0.01800 -0.09980 -0.16739 0.01800" size="0.0022" material="planned_path" contype="0" conaffinity="0" /><geom name="planned_path_seg_065" type="capsule" fromto="-0.09980 -0.16739 0.01800 -0.09742 -0.17496 0.01800" size="0.0022" material="planned_path" contype="0" conaffinity="0" /><geom name="planned_path_seg_066" type="capsule" fromto="-0.09742 -0.17496 0.01800 -0.09094 -0.17929 0.01800" size="0.0022" material="planned_path" contype="0" conaffinity="0" /><geom name="planned_path_seg_067" type="capsule" fromto="-0.09094 -0.17929 0.01800 -0.08291 -0.18000 0.01800" size="0.0022" material="planned_path" contype="0" conaffinity="0" /><geom name="planned_path_seg_068" type="capsule" fromto="-0.08291 -0.18000 0.01800 -0.07482 -0.18000 0.01800" size="0.0022" material="planned_path" contype="0" conaffinity="0" /><geom name="planned_path_seg_069" type="capsule" fromto="-0.07482 -0.18000 0.01800 -0.06673 -0.18000 0.01800" size="0.0022" material="planned_path" contype="0" conaffinity="0" /><geom name="planned_path_seg_070" type="capsule" fromto="-0.06673 -0.18000 0.01800 -0.05864 -0.18000 0.01800" size="0.0022" material="planned_path" contype="0" conaffinity="0" /><geom name="planned_path_seg_071" type="capsule" fromto="-0.05864 -0.18000 0.01800 -0.05055 -0.18000 0.01800" size="0.0022" material="planned_path" contype="0" conaffinity="0" /><geom name="planned_path_seg_072" type="capsule" fromto="-0.05055 -0.18000 0.01800 -0.04247 -0.18000 0.01800" size="0.0022" material="planned_path" contype="0" conaffinity="0" /><geom name="planned_path_seg_073" type="capsule" fromto="-0.04247 -0.18000 0.01800 -0.03438 -0.18000 0.01800" size="0.0022" material="planned_path" contype="0" conaffinity="0" /><geom name="planned_path_seg_074" type="capsule" fromto="-0.03438 -0.18000 0.01800 -0.02629 -0.18000 0.01800" size="0.0022" material="planned_path" contype="0" conaffinity="0" /><geom name="planned_path_seg_075" type="capsule" fromto="-0.02629 -0.18000 0.01800 -0.01820 -0.18000 0.01800" size="0.0022" material="planned_path" contype="0" conaffinity="0" /><geom name="planned_path_seg_076" type="capsule" fromto="-0.01820 -0.18000 0.01800 -0.01011 -0.18000 0.01800" size="0.0022" material="planned_path" contype="0" conaffinity="0" /><geom name="planned_path_seg_077" type="capsule" fromto="-0.01011 -0.18000 0.01800 -0.00203 -0.18000 0.01800" size="0.0022" material="planned_path" contype="0" conaffinity="0" /><geom name="planned_path_seg_078" type="capsule" fromto="-0.00203 -0.18000 0.01800 0.00606 -0.18000 0.01800" size="0.0022" material="planned_path" contype="0" conaffinity="0" /><geom name="planned_path_seg_079" type="capsule" fromto="0.00606 -0.18000 0.01800 0.01415 -0.18000 0.01800" size="0.0022" material="planned_path" contype="0" conaffinity="0" /><geom name="planned_path_seg_080" type="capsule" fromto="0.01415 -0.18000 0.01800 0.02224 -0.18000 0.01800" size="0.0022" material="planned_path" contype="0" conaffinity="0" /><geom name="planned_path_seg_081" type="capsule" fromto="0.02224 -0.18000 0.01800 0.03033 -0.18000 0.01800" size="0.0022" material="planned_path" contype="0" conaffinity="0" /><geom name="planned_path_seg_082" type="capsule" fromto="0.03033 -0.18000 0.01800 0.03842 -0.18000 0.01800" size="0.0022" material="planned_path" contype="0" conaffinity="0" /><geom name="planned_path_seg_083" type="capsule" fromto="0.03842 -0.18000 0.01800 0.04650 -0.17993 0.01800" size="0.0022" material="planned_path" contype="0" conaffinity="0" /><geom name="planned_path_seg_084" type="capsule" fromto="0.04650 -0.17993 0.01800 0.05419 -0.17789 0.01800" size="0.0022" material="planned_path" contype="0" conaffinity="0" /><geom name="planned_path_seg_085" type="capsule" fromto="0.05419 -0.17789 0.01800 0.05917 -0.17184 0.01800" size="0.0022" material="planned_path" contype="0" conaffinity="0" /><geom name="planned_path_seg_086" type="capsule" fromto="0.05917 -0.17184 0.01800 0.06000 -0.16381 0.01800" size="0.0022" material="planned_path" contype="0" conaffinity="0" /><geom name="planned_path_seg_087" type="capsule" fromto="0.06000 -0.16381 0.01800 0.06000 -0.15572 0.01800" size="0.0022" material="planned_path" contype="0" conaffinity="0" /><geom name="planned_path_seg_088" type="capsule" fromto="0.06000 -0.15572 0.01800 0.06000 -0.14764 0.01800" size="0.0022" material="planned_path" contype="0" conaffinity="0" /><geom name="planned_path_seg_089" type="capsule" fromto="0.06000 -0.14764 0.01800 0.06000 -0.13955 0.01800" size="0.0022" material="planned_path" contype="0" conaffinity="0" /><geom name="planned_path_seg_090" type="capsule" fromto="0.06000 -0.13955 0.01800 0.06000 -0.13146 0.01800" size="0.0022" material="planned_path" contype="0" conaffinity="0" /><geom name="planned_path_seg_091" type="capsule" fromto="0.06000 -0.13146 0.01800 0.06000 -0.12337 0.01800" size="0.0022" material="planned_path" contype="0" conaffinity="0" /><geom name="planned_path_seg_092" type="capsule" fromto="0.06000 -0.12337 0.01800 0.06000 -0.11528 0.01800" size="0.0022" material="planned_path" contype="0" conaffinity="0" /><geom name="planned_path_seg_093" type="capsule" fromto="0.06000 -0.11528 0.01800 0.06119 -0.10735 0.01800" size="0.0022" material="planned_path" contype="0" conaffinity="0" /><geom name="planned_path_seg_094" type="capsule" fromto="0.06119 -0.10735 0.01800 0.06659 -0.10165 0.01800" size="0.0022" material="planned_path" contype="0" conaffinity="0" /><geom name="planned_path_seg_095" type="capsule" fromto="0.06659 -0.10165 0.01800 0.07440 -0.10000 0.01800" size="0.0022" material="planned_path" contype="0" conaffinity="0" /><geom name="planned_path_seg_096" type="capsule" fromto="0.07440 -0.10000 0.01800 0.08249 -0.10000 0.01800" size="0.0022" material="planned_path" contype="0" conaffinity="0" /><geom name="planned_path_seg_097" type="capsule" fromto="0.08249 -0.10000 0.01800 0.09058 -0.10000 0.01800" size="0.0022" material="planned_path" contype="0" conaffinity="0" /><geom name="planned_path_seg_098" type="capsule" fromto="0.09058 -0.10000 0.01800 0.09867 -0.10000 0.01800" size="0.0022" material="planned_path" contype="0" conaffinity="0" /><geom name="planned_path_seg_099" type="capsule" fromto="0.09867 -0.10000 0.01800 0.10675 -0.10000 0.01800" size="0.0022" material="planned_path" contype="0" conaffinity="0" /><geom name="planned_path_seg_100" type="capsule" fromto="0.10675 -0.10000 0.01800 0.11484 -0.10000 0.01800" size="0.0022" material="planned_path" contype="0" conaffinity="0" /><geom name="planned_path_seg_101" type="capsule" fromto="0.11484 -0.10000 0.01800 0.12293 -0.10000 0.01800" size="0.0022" material="planned_path" contype="0" conaffinity="0" /><geom name="planned_path_seg_102" type="capsule" fromto="0.12293 -0.10000 0.01800 0.13097 -0.09929 0.01800" size="0.0022" material="planned_path" contype="0" conaffinity="0" /><geom name="planned_path_seg_103" type="capsule" fromto="0.13097 -0.09929 0.01800 0.13744 -0.09494 0.01800" size="0.0022" material="planned_path" contype="0" conaffinity="0" /><geom name="planned_path_seg_104" type="capsule" fromto="0.13744 -0.09494 0.01800 0.13980 -0.08737 0.01800" size="0.0022" material="planned_path" contype="0" conaffinity="0" /><geom name="planned_path_seg_105" type="capsule" fromto="0.13980 -0.08737 0.01800 0.14000 -0.07930 0.01800" size="0.0022" material="planned_path" contype="0" conaffinity="0" /><geom name="planned_path_seg_106" type="capsule" fromto="0.14000 -0.07930 0.01800 0.14000 -0.07121 0.01800" size="0.0022" material="planned_path" contype="0" conaffinity="0" /><geom name="planned_path_seg_107" type="capsule" fromto="0.14000 -0.07121 0.01800 0.14000 -0.06312 0.01800" size="0.0022" material="planned_path" contype="0" conaffinity="0" /><geom name="planned_path_seg_108" type="capsule" fromto="0.14000 -0.06312 0.01800 0.14000 -0.05503 0.01800" size="0.0022" material="planned_path" contype="0" conaffinity="0" /><geom name="planned_path_seg_109" type="capsule" fromto="0.14000 -0.05503 0.01800 0.14000 -0.04694 0.01800" size="0.0022" material="planned_path" contype="0" conaffinity="0" /><geom name="planned_path_seg_110" type="capsule" fromto="0.14000 -0.04694 0.01800 0.14000 -0.03886 0.01800" size="0.0022" material="planned_path" contype="0" conaffinity="0" /><geom name="planned_path_seg_111" type="capsule" fromto="0.14000 -0.03886 0.01800 0.14000 -0.03077 0.01800" size="0.0022" material="planned_path" contype="0" conaffinity="0" /><geom name="planned_path_seg_112" type="capsule" fromto="0.14000 -0.03077 0.01800 0.14000 -0.02268 0.01800" size="0.0022" material="planned_path" contype="0" conaffinity="0" /><geom name="planned_path_seg_113" type="capsule" fromto="0.14000 -0.02268 0.01800 0.14000 -0.01459 0.01800" size="0.0022" material="planned_path" contype="0" conaffinity="0" /><geom name="planned_path_seg_114" type="capsule" fromto="0.14000 -0.01459 0.01800 0.14000 -0.00650 0.01800" size="0.0022" material="planned_path" contype="0" conaffinity="0" /><geom name="planned_path_seg_115" type="capsule" fromto="0.14000 -0.00650 0.01800 0.14000 -0.00365 0.01743" size="0.0022" material="planned_path" contype="0" conaffinity="0" /><geom name="planned_path_seg_116" type="capsule" fromto="0.14000 -0.00365 0.01743 0.14000 0.00336 0.02148" size="0.0022" material="planned_path" contype="0" conaffinity="0" /><geom name="planned_path_seg_117" type="capsule" fromto="0.14000 0.00336 0.02148 0.14000 0.01036 0.02552" size="0.0022" material="planned_path" contype="0" conaffinity="0" /><geom name="planned_path_seg_118" type="capsule" fromto="0.14000 0.01036 0.02552 0.14000 0.01737 0.02956" size="0.0022" material="planned_path" contype="0" conaffinity="0" /><geom name="planned_path_seg_119" type="capsule" fromto="0.14000 0.01737 0.02956 0.14000 0.02437 0.03361" size="0.0022" material="planned_path" contype="0" conaffinity="0" /><geom name="planned_path_seg_120" type="capsule" fromto="0.14000 0.02437 0.03361 0.14000 0.03137 0.03765" size="0.0022" material="planned_path" contype="0" conaffinity="0" /><geom name="planned_path_seg_121" type="capsule" fromto="0.14000 0.03137 0.03765 0.13942 0.03834 0.04168" size="0.0022" material="planned_path" contype="0" conaffinity="0" /><geom name="planned_path_seg_122" type="capsule" fromto="0.13942 0.03834 0.04168 0.13572 0.04432 0.04512" size="0.0022" material="planned_path" contype="0" conaffinity="0" /><geom name="planned_path_seg_123" type="capsule" fromto="0.13572 0.04432 0.04512 0.12827 0.04666 0.04648" size="0.0022" material="planned_path" contype="0" conaffinity="0" /><geom name="planned_path_seg_124" type="capsule" fromto="0.12827 0.04666 0.04648 0.12020 0.04694 0.04664" size="0.0022" material="planned_path" contype="0" conaffinity="0" /><geom name="planned_path_seg_125" type="capsule" fromto="0.12020 0.04694 0.04664 0.11211 0.04694 0.04664" size="0.0022" material="planned_path" contype="0" conaffinity="0" /><geom name="planned_path_seg_126" type="capsule" fromto="0.11211 0.04694 0.04664 0.10403 0.04694 0.04664" size="0.0022" material="planned_path" contype="0" conaffinity="0" /><geom name="planned_path_seg_127" type="capsule" fromto="0.10403 0.04694 0.04664 0.09594 0.04694 0.04664" size="0.0022" material="planned_path" contype="0" conaffinity="0" /><geom name="planned_path_seg_128" type="capsule" fromto="0.09594 0.04694 0.04664 0.08785 0.04694 0.04664" size="0.0022" material="planned_path" contype="0" conaffinity="0" /><geom name="planned_path_seg_129" type="capsule" fromto="0.08785 0.04694 0.04664 0.07976 0.04694 0.04664" size="0.0022" material="planned_path" contype="0" conaffinity="0" /><geom name="planned_path_seg_130" type="capsule" fromto="0.07976 0.04694 0.04664 0.07167 0.04694 0.04664" size="0.0022" material="planned_path" contype="0" conaffinity="0" /><geom name="planned_path_seg_131" type="capsule" fromto="0.07167 0.04694 0.04664 0.06358 0.04694 0.04664" size="0.0022" material="planned_path" contype="0" conaffinity="0" /><geom name="planned_path_seg_132" type="capsule" fromto="0.06358 0.04694 0.04664 0.05550 0.04694 0.04664" size="0.0022" material="planned_path" contype="0" conaffinity="0" /><geom name="planned_path_seg_133" type="capsule" fromto="0.05550 0.04694 0.04664 0.04741 0.04694 0.04664" size="0.0022" material="planned_path" contype="0" conaffinity="0" /><geom name="planned_path_seg_134" type="capsule" fromto="0.04741 0.04694 0.04664 0.03932 0.04694 0.04664" size="0.0022" material="planned_path" contype="0" conaffinity="0" /><geom name="planned_path_seg_135" type="capsule" fromto="0.03932 0.04694 0.04664 0.03123 0.04694 0.04664" size="0.0022" material="planned_path" contype="0" conaffinity="0" /><geom name="planned_path_seg_136" type="capsule" fromto="0.03123 0.04694 0.04664 0.02314 0.04694 0.04664" size="0.0022" material="planned_path" contype="0" conaffinity="0" /><geom name="planned_path_seg_137" type="capsule" fromto="0.02314 0.04694 0.04664 0.01506 0.04694 0.04664" size="0.0022" material="planned_path" contype="0" conaffinity="0" /><geom name="planned_path_seg_138" type="capsule" fromto="0.01506 0.04694 0.04664 0.00697 0.04694 0.04664" size="0.0022" material="planned_path" contype="0" conaffinity="0" /><geom name="planned_path_seg_139" type="capsule" fromto="0.00697 0.04694 0.04664 -0.00112 0.04694 0.04664" size="0.0022" material="planned_path" contype="0" conaffinity="0" /><geom name="planned_path_seg_140" type="capsule" fromto="-0.00112 0.04694 0.04664 -0.00921 0.04694 0.04664" size="0.0022" material="planned_path" contype="0" conaffinity="0" /><geom name="planned_path_seg_141" type="capsule" fromto="-0.00921 0.04694 0.04664 -0.01730 0.04694 0.04664" size="0.0022" material="planned_path" contype="0" conaffinity="0" /><geom name="planned_path_seg_142" type="capsule" fromto="-0.01730 0.04694 0.04664 -0.02538 0.04694 0.04664" size="0.0022" material="planned_path" contype="0" conaffinity="0" /><geom name="planned_path_seg_143" type="capsule" fromto="-0.02538 0.04694 0.04664 -0.03347 0.04694 0.04664" size="0.0022" material="planned_path" contype="0" conaffinity="0" /><geom name="planned_path_seg_144" type="capsule" fromto="-0.03347 0.04694 0.04664 -0.04156 0.04694 0.04664" size="0.0022" material="planned_path" contype="0" conaffinity="0" /><geom name="planned_path_seg_145" type="capsule" fromto="-0.04156 0.04694 0.04664 -0.04965 0.04694 0.04664" size="0.0022" material="planned_path" contype="0" conaffinity="0" /><geom name="planned_path_seg_146" type="capsule" fromto="-0.04965 0.04694 0.04664 -0.05774 0.04694 0.04664" size="0.0022" material="planned_path" contype="0" conaffinity="0" /><geom name="planned_path_seg_147" type="capsule" fromto="-0.05774 0.04694 0.04664 -0.06582 0.04694 0.04664" size="0.0022" material="planned_path" contype="0" conaffinity="0" /><geom name="planned_path_seg_148" type="capsule" fromto="-0.06582 0.04694 0.04664 -0.07391 0.04694 0.04664" size="0.0022" material="planned_path" contype="0" conaffinity="0" /><geom name="planned_path_seg_149" type="capsule" fromto="-0.07391 0.04694 0.04664 -0.08200 0.04694 0.04664" size="0.0022" material="planned_path" contype="0" conaffinity="0" /><geom name="planned_path_seg_150" type="capsule" fromto="-0.08200 0.04694 0.04664 -0.09005 0.04744 0.04693" size="0.0022" material="planned_path" contype="0" conaffinity="0" /><geom name="planned_path_seg_151" type="capsule" fromto="-0.09005 0.04744 0.04693 -0.09696 0.05063 0.04877" size="0.0022" material="planned_path" contype="0" conaffinity="0" /><geom name="planned_path_seg_152" type="capsule" fromto="-0.09696 0.05063 0.04877 -0.09967 0.05708 0.05249" size="0.0022" material="planned_path" contype="0" conaffinity="0" /><geom name="planned_path_seg_153" type="capsule" fromto="-0.09967 0.05708 0.05249 -0.10000 0.06407 0.05653" size="0.0022" material="planned_path" contype="0" conaffinity="0" /><geom name="planned_path_seg_154" type="capsule" fromto="-0.10000 0.06407 0.05653 -0.10000 0.07107 0.06057" size="0.0022" material="planned_path" contype="0" conaffinity="0" /><geom name="planned_path_seg_155" type="capsule" fromto="-0.10000 0.07107 0.06057 -0.10000 0.07807 0.06461" size="0.0022" material="planned_path" contype="0" conaffinity="0" /><geom name="planned_path_seg_156" type="capsule" fromto="-0.10000 0.07807 0.06461 -0.10000 0.08508 0.06866" size="0.0022" material="planned_path" contype="0" conaffinity="0" /><geom name="planned_path_seg_157" type="capsule" fromto="-0.10000 0.08508 0.06866 -0.10000 0.09208 0.07270" size="0.0022" material="planned_path" contype="0" conaffinity="0" /><geom name="planned_path_seg_158" type="capsule" fromto="-0.10000 0.09208 0.07270 -0.10000 0.09909 0.07675" size="0.0022" material="planned_path" contype="0" conaffinity="0" /><geom name="planned_path_seg_159" type="capsule" fromto="-0.10000 0.09909 0.07675 -0.09967 0.10607 0.08078" size="0.0022" material="planned_path" contype="0" conaffinity="0" /><geom name="planned_path_seg_160" type="capsule" fromto="-0.09967 0.10607 0.08078 -0.09696 0.11252 0.08450" size="0.0022" material="planned_path" contype="0" conaffinity="0" /><geom name="planned_path_seg_161" type="capsule" fromto="-0.09696 0.11252 0.08450 -0.09006 0.11572 0.08635" size="0.0022" material="planned_path" contype="0" conaffinity="0" /><geom name="planned_path_seg_162" type="capsule" fromto="-0.09006 0.11572 0.08635 -0.08201 0.11622 0.08664" size="0.0022" material="planned_path" contype="0" conaffinity="0" /><geom name="planned_path_seg_163" type="capsule" fromto="-0.08201 0.11622 0.08664 -0.07392 0.11622 0.08664" size="0.0022" material="planned_path" contype="0" conaffinity="0" /><geom name="planned_path_seg_164" type="capsule" fromto="-0.07392 0.11622 0.08664 -0.06584 0.11622 0.08664" size="0.0022" material="planned_path" contype="0" conaffinity="0" /><geom name="planned_path_seg_165" type="capsule" fromto="-0.06584 0.11622 0.08664 -0.05775 0.11622 0.08664" size="0.0022" material="planned_path" contype="0" conaffinity="0" /><geom name="planned_path_seg_166" type="capsule" fromto="-0.05775 0.11622 0.08664 -0.04966 0.11622 0.08664" size="0.0022" material="planned_path" contype="0" conaffinity="0" /><geom name="planned_path_seg_167" type="capsule" fromto="-0.04966 0.11622 0.08664 -0.04157 0.11622 0.08664" size="0.0022" material="planned_path" contype="0" conaffinity="0" /><geom name="planned_path_seg_168" type="capsule" fromto="-0.04157 0.11622 0.08664 -0.03348 0.11622 0.08664" size="0.0022" material="planned_path" contype="0" conaffinity="0" /><geom name="planned_path_seg_169" type="capsule" fromto="-0.03348 0.11622 0.08664 -0.02540 0.11622 0.08664" size="0.0022" material="planned_path" contype="0" conaffinity="0" /><geom name="planned_path_seg_170" type="capsule" fromto="-0.02540 0.11622 0.08664 -0.01731 0.11622 0.08664" size="0.0022" material="planned_path" contype="0" conaffinity="0" /><geom name="planned_path_seg_171" type="capsule" fromto="-0.01731 0.11622 0.08664 -0.00922 0.11622 0.08664" size="0.0022" material="planned_path" contype="0" conaffinity="0" /><geom name="planned_path_seg_172" type="capsule" fromto="-0.00922 0.11622 0.08664 -0.00113 0.11622 0.08664" size="0.0022" material="planned_path" contype="0" conaffinity="0" /><geom name="planned_path_seg_173" type="capsule" fromto="-0.00113 0.11622 0.08664 0.00696 0.11622 0.08664" size="0.0022" material="planned_path" contype="0" conaffinity="0" /><geom name="planned_path_seg_174" type="capsule" fromto="0.00696 0.11622 0.08664 0.01504 0.11622 0.08664" size="0.0022" material="planned_path" contype="0" conaffinity="0" /><geom name="planned_path_seg_175" type="capsule" fromto="0.01504 0.11622 0.08664 0.02313 0.11622 0.08664" size="0.0022" material="planned_path" contype="0" conaffinity="0" /><geom name="planned_path_seg_176" type="capsule" fromto="0.02313 0.11622 0.08664 0.03122 0.11622 0.08664" size="0.0022" material="planned_path" contype="0" conaffinity="0" /><geom name="planned_path_seg_177" type="capsule" fromto="0.03122 0.11622 0.08664 0.03931 0.11622 0.08664" size="0.0022" material="planned_path" contype="0" conaffinity="0" /><geom name="planned_path_seg_178" type="capsule" fromto="0.03931 0.11622 0.08664 0.04740 0.11622 0.08664" size="0.0022" material="planned_path" contype="0" conaffinity="0" /><geom name="planned_path_seg_179" type="capsule" fromto="0.04740 0.11622 0.08664 0.05548 0.11622 0.08664" size="0.0022" material="planned_path" contype="0" conaffinity="0" /><geom name="planned_path_seg_180" type="capsule" fromto="0.05548 0.11622 0.08664 0.06357 0.11622 0.08664" size="0.0022" material="planned_path" contype="0" conaffinity="0" /><geom name="planned_path_seg_181" type="capsule" fromto="0.06357 0.11622 0.08664 0.07166 0.11622 0.08664" size="0.0022" material="planned_path" contype="0" conaffinity="0" /><geom name="planned_path_seg_182" type="capsule" fromto="0.07166 0.11622 0.08664 0.07975 0.11622 0.08664" size="0.0022" material="planned_path" contype="0" conaffinity="0" /><geom name="planned_path_seg_183" type="capsule" fromto="0.07975 0.11622 0.08664 0.08784 0.11622 0.08664" size="0.0022" material="planned_path" contype="0" conaffinity="0" /><geom name="planned_path_seg_184" type="capsule" fromto="0.08784 0.11622 0.08664 0.09592 0.11622 0.08664" size="0.0022" material="planned_path" contype="0" conaffinity="0" /><geom name="planned_path_seg_185" type="capsule" fromto="0.09592 0.11622 0.08664 0.10401 0.11622 0.08664" size="0.0022" material="planned_path" contype="0" conaffinity="0" /><geom name="planned_path_seg_186" type="capsule" fromto="0.10401 0.11622 0.08664 0.11210 0.11622 0.08664" size="0.0022" material="planned_path" contype="0" conaffinity="0" /><geom name="planned_path_seg_187" type="capsule" fromto="0.11210 0.11622 0.08664 0.12019 0.11622 0.08664" size="0.0022" material="planned_path" contype="0" conaffinity="0" /><geom name="planned_path_seg_188" type="capsule" fromto="0.12019 0.11622 0.08664 0.12825 0.11650 0.08680" size="0.0022" material="planned_path" contype="0" conaffinity="0" /><geom name="planned_path_seg_189" type="capsule" fromto="0.12825 0.11650 0.08680 0.13571 0.11884 0.08815" size="0.0022" material="planned_path" contype="0" conaffinity="0" /><geom name="planned_path_seg_190" type="capsule" fromto="0.13571 0.11884 0.08815 0.13942 0.12481 0.09160" size="0.0022" material="planned_path" contype="0" conaffinity="0" /><geom name="planned_path_seg_191" type="capsule" fromto="0.13942 0.12481 0.09160 0.14000 0.13178 0.09562" size="0.0022" material="planned_path" contype="0" conaffinity="0" /><geom name="planned_path_seg_192" type="capsule" fromto="0.14000 0.13178 0.09562 0.14001 0.13878 0.09966" size="0.0022" material="planned_path" contype="0" conaffinity="0" /><geom name="planned_path_seg_193" type="capsule" fromto="0.14001 0.13878 0.09966 0.14188 0.14549 0.10354" size="0.0022" material="planned_path" contype="0" conaffinity="0" /><geom name="planned_path_seg_194" type="capsule" fromto="0.14188 0.14549 0.10354 0.14773 0.15003 0.10616" size="0.0022" material="planned_path" contype="0" conaffinity="0" /><geom name="planned_path_seg_195" type="capsule" fromto="0.14773 0.15003 0.10616 0.15574 0.15086 0.10664" size="0.0022" material="planned_path" contype="0" conaffinity="0" /><geom name="planned_path_seg_196" type="capsule" fromto="0.15574 0.15086 0.10664 0.16382 0.15086 0.10664" size="0.0022" material="planned_path" contype="0" conaffinity="0" /><geom name="planned_path_seg_197" type="capsule" fromto="0.16382 0.15086 0.10664 0.17191 0.15086 0.10664" size="0.0022" material="planned_path" contype="0" conaffinity="0" /><geom name="planned_path_seg_198" type="capsule" fromto="0.17191 0.15086 0.10664 0.18000 0.15086 0.10664" size="0.0022" material="planned_path" contype="0" conaffinity="0" /><geom name="planned_waypoint_000" type="sphere" pos="-0.18000 -0.18000 0.01800" size="0.007" material="planned_start" contype="0" conaffinity="0" /><geom name="planned_waypoint_001" type="sphere" pos="-0.18000 -0.17191 0.01800" size="0.0032" material="planned_waypoint" contype="0" conaffinity="0" /><geom name="planned_waypoint_002" type="sphere" pos="-0.18000 -0.16382 0.01800" size="0.0032" material="planned_waypoint" contype="0" conaffinity="0" /><geom name="planned_waypoint_003" type="sphere" pos="-0.18000 -0.15574 0.01800" size="0.0032" material="planned_waypoint" contype="0" conaffinity="0" /><geom name="planned_waypoint_004" type="sphere" pos="-0.18000 -0.14765 0.01800" size="0.0032" material="planned_waypoint" contype="0" conaffinity="0" /><geom name="planned_waypoint_005" type="sphere" pos="-0.18000 -0.13956 0.01800" size="0.0032" material="planned_waypoint" contype="0" conaffinity="0" /><geom name="planned_waypoint_006" type="sphere" pos="-0.18000 -0.13147 0.01800" size="0.0032" material="planned_waypoint" contype="0" conaffinity="0" /><geom name="planned_waypoint_007" type="sphere" pos="-0.18000 -0.12338 0.01800" size="0.0032" material="planned_waypoint" contype="0" conaffinity="0" /><geom name="planned_waypoint_008" type="sphere" pos="-0.18000 -0.11530 0.01800" size="0.0032" material="planned_waypoint" contype="0" conaffinity="0" /><geom name="planned_waypoint_009" type="sphere" pos="-0.18000 -0.10721 0.01800" size="0.0032" material="planned_waypoint" contype="0" conaffinity="0" /><geom name="planned_waypoint_010" type="sphere" pos="-0.18000 -0.09912 0.01800" size="0.0032" material="planned_waypoint" contype="0" conaffinity="0" /><geom name="planned_waypoint_011" type="sphere" pos="-0.18000 -0.09103 0.01800" size="0.0032" material="planned_waypoint" contype="0" conaffinity="0" /><geom name="planned_waypoint_012" type="sphere" pos="-0.18000 -0.08294 0.01800" size="0.0032" material="planned_waypoint" contype="0" conaffinity="0" /><geom name="planned_waypoint_013" type="sphere" pos="-0.18000 -0.07486 0.01800" size="0.0032" material="planned_waypoint" contype="0" conaffinity="0" /><geom name="planned_waypoint_014" type="sphere" pos="-0.18000 -0.06677 0.01800" size="0.0032" material="planned_waypoint" contype="0" conaffinity="0" /><geom name="planned_waypoint_015" type="sphere" pos="-0.18000 -0.05868 0.01800" size="0.0032" material="planned_waypoint" contype="0" conaffinity="0" /><geom name="planned_waypoint_016" type="sphere" pos="-0.18000 -0.05059 0.01800" size="0.0032" material="planned_waypoint" contype="0" conaffinity="0" /><geom name="planned_waypoint_017" type="sphere" pos="-0.18000 -0.04250 0.01800" size="0.0032" material="planned_waypoint" contype="0" conaffinity="0" /><geom name="planned_waypoint_018" type="sphere" pos="-0.18000 -0.03442 0.01800" size="0.0032" material="planned_waypoint" contype="0" conaffinity="0" /><geom name="planned_waypoint_019" type="sphere" pos="-0.17836 -0.02660 0.01800" size="0.0032" material="planned_waypoint" contype="0" conaffinity="0" /><geom name="planned_waypoint_020" type="sphere" pos="-0.17267 -0.02120 0.01800" size="0.0032" material="planned_waypoint" contype="0" conaffinity="0" /><geom name="planned_waypoint_021" type="sphere" pos="-0.16473 -0.02000 0.01800" size="0.0032" material="planned_waypoint" contype="0" conaffinity="0" /><geom name="planned_waypoint_022" type="sphere" pos="-0.15664 -0.02000 0.01800" size="0.0032" material="planned_waypoint" contype="0" conaffinity="0" /><geom name="planned_waypoint_023" type="sphere" pos="-0.14855 -0.02000 0.01800" size="0.0032" material="planned_waypoint" contype="0" conaffinity="0" /><geom name="planned_waypoint_024" type="sphere" pos="-0.14047 -0.02000 0.01800" size="0.0032" material="planned_waypoint" contype="0" conaffinity="0" /><geom name="planned_waypoint_025" type="sphere" pos="-0.13238 -0.02000 0.01800" size="0.0032" material="planned_waypoint" contype="0" conaffinity="0" /><geom name="planned_waypoint_026" type="sphere" pos="-0.12429 -0.02000 0.01800" size="0.0032" material="planned_waypoint" contype="0" conaffinity="0" /><geom name="planned_waypoint_027" type="sphere" pos="-0.11620 -0.02000 0.01800" size="0.0032" material="planned_waypoint" contype="0" conaffinity="0" /><geom name="planned_waypoint_028" type="sphere" pos="-0.10811 -0.02000 0.01800" size="0.0032" material="planned_waypoint" contype="0" conaffinity="0" /><geom name="planned_waypoint_029" type="sphere" pos="-0.10003 -0.02000 0.01800" size="0.0032" material="planned_waypoint" contype="0" conaffinity="0" /><geom name="planned_waypoint_030" type="sphere" pos="-0.09194 -0.02000 0.01800" size="0.0032" material="planned_waypoint" contype="0" conaffinity="0" /><geom name="planned_waypoint_031" type="sphere" pos="-0.08385 -0.02000 0.01800" size="0.0032" material="planned_waypoint" contype="0" conaffinity="0" /><geom name="planned_waypoint_032" type="sphere" pos="-0.07576 -0.02000 0.01800" size="0.0032" material="planned_waypoint" contype="0" conaffinity="0" /><geom name="planned_waypoint_033" type="sphere" pos="-0.06767 -0.02000 0.01800" size="0.0032" material="planned_waypoint" contype="0" conaffinity="0" /><geom name="planned_waypoint_034" type="sphere" pos="-0.05959 -0.02000 0.01800" size="0.0032" material="planned_waypoint" contype="0" conaffinity="0" /><geom name="planned_waypoint_035" type="sphere" pos="-0.05150 -0.02000 0.01800" size="0.0032" material="planned_waypoint" contype="0" conaffinity="0" /><geom name="planned_waypoint_036" type="sphere" pos="-0.04341 -0.02000 0.01800" size="0.0032" material="planned_waypoint" contype="0" conaffinity="0" /><geom name="planned_waypoint_037" type="sphere" pos="-0.03532 -0.02000 0.01800" size="0.0032" material="planned_waypoint" contype="0" conaffinity="0" /><geom name="planned_waypoint_038" type="sphere" pos="-0.02738 -0.02117 0.01800" size="0.0032" material="planned_waypoint" contype="0" conaffinity="0" /><geom name="planned_waypoint_039" type="sphere" pos="-0.02167 -0.02656 0.01800" size="0.0032" material="planned_waypoint" contype="0" conaffinity="0" /><geom name="planned_waypoint_040" type="sphere" pos="-0.02000 -0.03436 0.01800" size="0.0032" material="planned_waypoint" contype="0" conaffinity="0" /><geom name="planned_waypoint_041" type="sphere" pos="-0.02000 -0.04245 0.01800" size="0.0032" material="planned_waypoint" contype="0" conaffinity="0" /><geom name="planned_waypoint_042" type="sphere" pos="-0.02000 -0.05054 0.01800" size="0.0032" material="planned_waypoint" contype="0" conaffinity="0" /><geom name="planned_waypoint_043" type="sphere" pos="-0.02000 -0.05863 0.01800" size="0.0032" material="planned_waypoint" contype="0" conaffinity="0" /><geom name="planned_waypoint_044" type="sphere" pos="-0.02000 -0.06672 0.01800" size="0.0032" material="planned_waypoint" contype="0" conaffinity="0" /><geom name="planned_waypoint_045" type="sphere" pos="-0.02000 -0.07480 0.01800" size="0.0032" material="planned_waypoint" contype="0" conaffinity="0" /><geom name="planned_waypoint_046" type="sphere" pos="-0.02000 -0.08289 0.01800" size="0.0032" material="planned_waypoint" contype="0" conaffinity="0" /><geom name="planned_waypoint_047" type="sphere" pos="-0.02070 -0.09093 0.01800" size="0.0032" material="planned_waypoint" contype="0" conaffinity="0" /><geom name="planned_waypoint_048" type="sphere" pos="-0.02503 -0.09742 0.01800" size="0.0032" material="planned_waypoint" contype="0" conaffinity="0" /><geom name="planned_waypoint_049" type="sphere" pos="-0.03259 -0.09980 0.01800" size="0.0032" material="planned_waypoint" contype="0" conaffinity="0" /><geom name="planned_waypoint_050" type="sphere" pos="-0.04067 -0.10000 0.01800" size="0.0032" material="planned_waypoint" contype="0" conaffinity="0" /><geom name="planned_waypoint_051" type="sphere" pos="-0.04875 -0.10000 0.01800" size="0.0032" material="planned_waypoint" contype="0" conaffinity="0" /><geom name="planned_waypoint_052" type="sphere" pos="-0.05684 -0.10000 0.01800" size="0.0032" material="planned_waypoint" contype="0" conaffinity="0" /><geom name="planned_waypoint_053" type="sphere" pos="-0.06493 -0.10000 0.01800" size="0.0032" material="planned_waypoint" contype="0" conaffinity="0" /><geom name="planned_waypoint_054" type="sphere" pos="-0.07302 -0.10000 0.01800" size="0.0032" material="planned_waypoint" contype="0" conaffinity="0" /><geom name="planned_waypoint_055" type="sphere" pos="-0.08111 -0.10000 0.01800" size="0.0032" material="planned_waypoint" contype="0" conaffinity="0" /><geom name="planned_waypoint_056" type="sphere" pos="-0.08916 -0.10045 0.01800" size="0.0032" material="planned_waypoint" contype="0" conaffinity="0" /><geom name="planned_waypoint_057" type="sphere" pos="-0.09649 -0.10350 0.01800" size="0.0032" material="planned_waypoint" contype="0" conaffinity="0" /><geom name="planned_waypoint_058" type="sphere" pos="-0.09955 -0.11082 0.01800" size="0.0032" material="planned_waypoint" contype="0" conaffinity="0" /><geom name="planned_waypoint_059" type="sphere" pos="-0.10000 -0.11888 0.01800" size="0.0032" material="planned_waypoint" contype="0" conaffinity="0" /><geom name="planned_waypoint_060" type="sphere" pos="-0.10000 -0.12697 0.01800" size="0.0032" material="planned_waypoint" contype="0" conaffinity="0" /><geom name="planned_waypoint_061" type="sphere" pos="-0.10000 -0.13506 0.01800" size="0.0032" material="planned_waypoint" contype="0" conaffinity="0" /><geom name="planned_waypoint_062" type="sphere" pos="-0.10000 -0.14314 0.01800" size="0.0032" material="planned_waypoint" contype="0" conaffinity="0" /><geom name="planned_waypoint_063" type="sphere" pos="-0.10000 -0.15123 0.01800" size="0.0032" material="planned_waypoint" contype="0" conaffinity="0" /><geom name="planned_waypoint_064" type="sphere" pos="-0.10000 -0.15932 0.01800" size="0.0032" material="planned_waypoint" contype="0" conaffinity="0" /><geom name="planned_waypoint_065" type="sphere" pos="-0.09980 -0.16739 0.01800" size="0.0032" material="planned_waypoint" contype="0" conaffinity="0" /><geom name="planned_waypoint_066" type="sphere" pos="-0.09742 -0.17496 0.01800" size="0.0032" material="planned_waypoint" contype="0" conaffinity="0" /><geom name="planned_waypoint_067" type="sphere" pos="-0.09094 -0.17929 0.01800" size="0.0032" material="planned_waypoint" contype="0" conaffinity="0" /><geom name="planned_waypoint_068" type="sphere" pos="-0.08291 -0.18000 0.01800" size="0.0032" material="planned_waypoint" contype="0" conaffinity="0" /><geom name="planned_waypoint_069" type="sphere" pos="-0.07482 -0.18000 0.01800" size="0.0032" material="planned_waypoint" contype="0" conaffinity="0" /><geom name="planned_waypoint_070" type="sphere" pos="-0.06673 -0.18000 0.01800" size="0.0032" material="planned_waypoint" contype="0" conaffinity="0" /><geom name="planned_waypoint_071" type="sphere" pos="-0.05864 -0.18000 0.01800" size="0.0032" material="planned_waypoint" contype="0" conaffinity="0" /><geom name="planned_waypoint_072" type="sphere" pos="-0.05055 -0.18000 0.01800" size="0.0032" material="planned_waypoint" contype="0" conaffinity="0" /><geom name="planned_waypoint_073" type="sphere" pos="-0.04247 -0.18000 0.01800" size="0.0032" material="planned_waypoint" contype="0" conaffinity="0" /><geom name="planned_waypoint_074" type="sphere" pos="-0.03438 -0.18000 0.01800" size="0.0032" material="planned_waypoint" contype="0" conaffinity="0" /><geom name="planned_waypoint_075" type="sphere" pos="-0.02629 -0.18000 0.01800" size="0.0032" material="planned_waypoint" contype="0" conaffinity="0" /><geom name="planned_waypoint_076" type="sphere" pos="-0.01820 -0.18000 0.01800" size="0.0032" material="planned_waypoint" contype="0" conaffinity="0" /><geom name="planned_waypoint_077" type="sphere" pos="-0.01011 -0.18000 0.01800" size="0.0032" material="planned_waypoint" contype="0" conaffinity="0" /><geom name="planned_waypoint_078" type="sphere" pos="-0.00203 -0.18000 0.01800" size="0.0032" material="planned_waypoint" contype="0" conaffinity="0" /><geom name="planned_waypoint_079" type="sphere" pos="0.00606 -0.18000 0.01800" size="0.0032" material="planned_waypoint" contype="0" conaffinity="0" /><geom name="planned_waypoint_080" type="sphere" pos="0.01415 -0.18000 0.01800" size="0.0032" material="planned_waypoint" contype="0" conaffinity="0" /><geom name="planned_waypoint_081" type="sphere" pos="0.02224 -0.18000 0.01800" size="0.0032" material="planned_waypoint" contype="0" conaffinity="0" /><geom name="planned_waypoint_082" type="sphere" pos="0.03033 -0.18000 0.01800" size="0.0032" material="planned_waypoint" contype="0" conaffinity="0" /><geom name="planned_waypoint_083" type="sphere" pos="0.03842 -0.18000 0.01800" size="0.0032" material="planned_waypoint" contype="0" conaffinity="0" /><geom name="planned_waypoint_084" type="sphere" pos="0.04650 -0.17993 0.01800" size="0.0032" material="planned_waypoint" contype="0" conaffinity="0" /><geom name="planned_waypoint_085" type="sphere" pos="0.05419 -0.17789 0.01800" size="0.0032" material="planned_waypoint" contype="0" conaffinity="0" /><geom name="planned_waypoint_086" type="sphere" pos="0.05917 -0.17184 0.01800" size="0.0032" material="planned_waypoint" contype="0" conaffinity="0" /><geom name="planned_waypoint_087" type="sphere" pos="0.06000 -0.16381 0.01800" size="0.0032" material="planned_waypoint" contype="0" conaffinity="0" /><geom name="planned_waypoint_088" type="sphere" pos="0.06000 -0.15572 0.01800" size="0.0032" material="planned_waypoint" contype="0" conaffinity="0" /><geom name="planned_waypoint_089" type="sphere" pos="0.06000 -0.14764 0.01800" size="0.0032" material="planned_waypoint" contype="0" conaffinity="0" /><geom name="planned_waypoint_090" type="sphere" pos="0.06000 -0.13955 0.01800" size="0.0032" material="planned_waypoint" contype="0" conaffinity="0" /><geom name="planned_waypoint_091" type="sphere" pos="0.06000 -0.13146 0.01800" size="0.0032" material="planned_waypoint" contype="0" conaffinity="0" /><geom name="planned_waypoint_092" type="sphere" pos="0.06000 -0.12337 0.01800" size="0.0032" material="planned_waypoint" contype="0" conaffinity="0" /><geom name="planned_waypoint_093" type="sphere" pos="0.06000 -0.11528 0.01800" size="0.0032" material="planned_waypoint" contype="0" conaffinity="0" /><geom name="planned_waypoint_094" type="sphere" pos="0.06119 -0.10735 0.01800" size="0.0032" material="planned_waypoint" contype="0" conaffinity="0" /><geom name="planned_waypoint_095" type="sphere" pos="0.06659 -0.10165 0.01800" size="0.0032" material="planned_waypoint" contype="0" conaffinity="0" /><geom name="planned_waypoint_096" type="sphere" pos="0.07440 -0.10000 0.01800" size="0.0032" material="planned_waypoint" contype="0" conaffinity="0" /><geom name="planned_waypoint_097" type="sphere" pos="0.08249 -0.10000 0.01800" size="0.0032" material="planned_waypoint" contype="0" conaffinity="0" /><geom name="planned_waypoint_098" type="sphere" pos="0.09058 -0.10000 0.01800" size="0.0032" material="planned_waypoint" contype="0" conaffinity="0" /><geom name="planned_waypoint_099" type="sphere" pos="0.09867 -0.10000 0.01800" size="0.0032" material="planned_waypoint" contype="0" conaffinity="0" /><geom name="planned_waypoint_100" type="sphere" pos="0.10675 -0.10000 0.01800" size="0.0032" material="planned_waypoint" contype="0" conaffinity="0" /><geom name="planned_waypoint_101" type="sphere" pos="0.11484 -0.10000 0.01800" size="0.0032" material="planned_waypoint" contype="0" conaffinity="0" /><geom name="planned_waypoint_102" type="sphere" pos="0.12293 -0.10000 0.01800" size="0.0032" material="planned_waypoint" contype="0" conaffinity="0" /><geom name="planned_waypoint_103" type="sphere" pos="0.13097 -0.09929 0.01800" size="0.0032" material="planned_waypoint" contype="0" conaffinity="0" /><geom name="planned_waypoint_104" type="sphere" pos="0.13744 -0.09494 0.01800" size="0.0032" material="planned_waypoint" contype="0" conaffinity="0" /><geom name="planned_waypoint_105" type="sphere" pos="0.13980 -0.08737 0.01800" size="0.0032" material="planned_waypoint" contype="0" conaffinity="0" /><geom name="planned_waypoint_106" type="sphere" pos="0.14000 -0.07930 0.01800" size="0.0032" material="planned_waypoint" contype="0" conaffinity="0" /><geom name="planned_waypoint_107" type="sphere" pos="0.14000 -0.07121 0.01800" size="0.0032" material="planned_waypoint" contype="0" conaffinity="0" /><geom name="planned_waypoint_108" type="sphere" pos="0.14000 -0.06312 0.01800" size="0.0032" material="planned_waypoint" contype="0" conaffinity="0" /><geom name="planned_waypoint_109" type="sphere" pos="0.14000 -0.05503 0.01800" size="0.0032" material="planned_waypoint" contype="0" conaffinity="0" /><geom name="planned_waypoint_110" type="sphere" pos="0.14000 -0.04694 0.01800" size="0.0032" material="planned_waypoint" contype="0" conaffinity="0" /><geom name="planned_waypoint_111" type="sphere" pos="0.14000 -0.03886 0.01800" size="0.0032" material="planned_waypoint" contype="0" conaffinity="0" /><geom name="planned_waypoint_112" type="sphere" pos="0.14000 -0.03077 0.01800" size="0.0032" material="planned_waypoint" contype="0" conaffinity="0" /><geom name="planned_waypoint_113" type="sphere" pos="0.14000 -0.02268 0.01800" size="0.0032" material="planned_waypoint" contype="0" conaffinity="0" /><geom name="planned_waypoint_114" type="sphere" pos="0.14000 -0.01459 0.01800" size="0.0032" material="planned_waypoint" contype="0" conaffinity="0" /><geom name="planned_waypoint_115" type="sphere" pos="0.14000 -0.00650 0.01800" size="0.0032" material="planned_waypoint" contype="0" conaffinity="0" /><geom name="planned_waypoint_116" type="sphere" pos="0.14000 -0.00365 0.01743" size="0.0032" material="planned_waypoint" contype="0" conaffinity="0" /><geom name="planned_waypoint_117" type="sphere" pos="0.14000 0.00336 0.02148" size="0.0032" material="planned_waypoint" contype="0" conaffinity="0" /><geom name="planned_waypoint_118" type="sphere" pos="0.14000 0.01036 0.02552" size="0.0032" material="planned_waypoint" contype="0" conaffinity="0" /><geom name="planned_waypoint_119" type="sphere" pos="0.14000 0.01737 0.02956" size="0.0032" material="planned_waypoint" contype="0" conaffinity="0" /><geom name="planned_waypoint_120" type="sphere" pos="0.14000 0.02437 0.03361" size="0.0032" material="planned_waypoint" contype="0" conaffinity="0" /><geom name="planned_waypoint_121" type="sphere" pos="0.14000 0.03137 0.03765" size="0.0032" material="planned_waypoint" contype="0" conaffinity="0" /><geom name="planned_waypoint_122" type="sphere" pos="0.13942 0.03834 0.04168" size="0.0032" material="planned_waypoint" contype="0" conaffinity="0" /><geom name="planned_waypoint_123" type="sphere" pos="0.13572 0.04432 0.04512" size="0.0032" material="planned_waypoint" contype="0" conaffinity="0" /><geom name="planned_waypoint_124" type="sphere" pos="0.12827 0.04666 0.04648" size="0.0032" material="planned_waypoint" contype="0" conaffinity="0" /><geom name="planned_waypoint_125" type="sphere" pos="0.12020 0.04694 0.04664" size="0.0032" material="planned_waypoint" contype="0" conaffinity="0" /><geom name="planned_waypoint_126" type="sphere" pos="0.11211 0.04694 0.04664" size="0.0032" material="planned_waypoint" contype="0" conaffinity="0" /><geom name="planned_waypoint_127" type="sphere" pos="0.10403 0.04694 0.04664" size="0.0032" material="planned_waypoint" contype="0" conaffinity="0" /><geom name="planned_waypoint_128" type="sphere" pos="0.09594 0.04694 0.04664" size="0.0032" material="planned_waypoint" contype="0" conaffinity="0" /><geom name="planned_waypoint_129" type="sphere" pos="0.08785 0.04694 0.04664" size="0.0032" material="planned_waypoint" contype="0" conaffinity="0" /><geom name="planned_waypoint_130" type="sphere" pos="0.07976 0.04694 0.04664" size="0.0032" material="planned_waypoint" contype="0" conaffinity="0" /><geom name="planned_waypoint_131" type="sphere" pos="0.07167 0.04694 0.04664" size="0.0032" material="planned_waypoint" contype="0" conaffinity="0" /><geom name="planned_waypoint_132" type="sphere" pos="0.06358 0.04694 0.04664" size="0.0032" material="planned_waypoint" contype="0" conaffinity="0" /><geom name="planned_waypoint_133" type="sphere" pos="0.05550 0.04694 0.04664" size="0.0032" material="planned_waypoint" contype="0" conaffinity="0" /><geom name="planned_waypoint_134" type="sphere" pos="0.04741 0.04694 0.04664" size="0.0032" material="planned_waypoint" contype="0" conaffinity="0" /><geom name="planned_waypoint_135" type="sphere" pos="0.03932 0.04694 0.04664" size="0.0032" material="planned_waypoint" contype="0" conaffinity="0" /><geom name="planned_waypoint_136" type="sphere" pos="0.03123 0.04694 0.04664" size="0.0032" material="planned_waypoint" contype="0" conaffinity="0" /><geom name="planned_waypoint_137" type="sphere" pos="0.02314 0.04694 0.04664" size="0.0032" material="planned_waypoint" contype="0" conaffinity="0" /><geom name="planned_waypoint_138" type="sphere" pos="0.01506 0.04694 0.04664" size="0.0032" material="planned_waypoint" contype="0" conaffinity="0" /><geom name="planned_waypoint_139" type="sphere" pos="0.00697 0.04694 0.04664" size="0.0032" material="planned_waypoint" contype="0" conaffinity="0" /><geom name="planned_waypoint_140" type="sphere" pos="-0.00112 0.04694 0.04664" size="0.0032" material="planned_waypoint" contype="0" conaffinity="0" /><geom name="planned_waypoint_141" type="sphere" pos="-0.00921 0.04694 0.04664" size="0.0032" material="planned_waypoint" contype="0" conaffinity="0" /><geom name="planned_waypoint_142" type="sphere" pos="-0.01730 0.04694 0.04664" size="0.0032" material="planned_waypoint" contype="0" conaffinity="0" /><geom name="planned_waypoint_143" type="sphere" pos="-0.02538 0.04694 0.04664" size="0.0032" material="planned_waypoint" contype="0" conaffinity="0" /><geom name="planned_waypoint_144" type="sphere" pos="-0.03347 0.04694 0.04664" size="0.0032" material="planned_waypoint" contype="0" conaffinity="0" /><geom name="planned_waypoint_145" type="sphere" pos="-0.04156 0.04694 0.04664" size="0.0032" material="planned_waypoint" contype="0" conaffinity="0" /><geom name="planned_waypoint_146" type="sphere" pos="-0.04965 0.04694 0.04664" size="0.0032" material="planned_waypoint" contype="0" conaffinity="0" /><geom name="planned_waypoint_147" type="sphere" pos="-0.05774 0.04694 0.04664" size="0.0032" material="planned_waypoint" contype="0" conaffinity="0" /><geom name="planned_waypoint_148" type="sphere" pos="-0.06582 0.04694 0.04664" size="0.0032" material="planned_waypoint" contype="0" conaffinity="0" /><geom name="planned_waypoint_149" type="sphere" pos="-0.07391 0.04694 0.04664" size="0.0032" material="planned_waypoint" contype="0" conaffinity="0" /><geom name="planned_waypoint_150" type="sphere" pos="-0.08200 0.04694 0.04664" size="0.0032" material="planned_waypoint" contype="0" conaffinity="0" /><geom name="planned_waypoint_151" type="sphere" pos="-0.09005 0.04744 0.04693" size="0.0032" material="planned_waypoint" contype="0" conaffinity="0" /><geom name="planned_waypoint_152" type="sphere" pos="-0.09696 0.05063 0.04877" size="0.0032" material="planned_waypoint" contype="0" conaffinity="0" /><geom name="planned_waypoint_153" type="sphere" pos="-0.09967 0.05708 0.05249" size="0.0032" material="planned_waypoint" contype="0" conaffinity="0" /><geom name="planned_waypoint_154" type="sphere" pos="-0.10000 0.06407 0.05653" size="0.0032" material="planned_waypoint" contype="0" conaffinity="0" /><geom name="planned_waypoint_155" type="sphere" pos="-0.10000 0.07107 0.06057" size="0.0032" material="planned_waypoint" contype="0" conaffinity="0" /><geom name="planned_waypoint_156" type="sphere" pos="-0.10000 0.07807 0.06461" size="0.0032" material="planned_waypoint" contype="0" conaffinity="0" /><geom name="planned_waypoint_157" type="sphere" pos="-0.10000 0.08508 0.06866" size="0.0032" material="planned_waypoint" contype="0" conaffinity="0" /><geom name="planned_waypoint_158" type="sphere" pos="-0.10000 0.09208 0.07270" size="0.0032" material="planned_waypoint" contype="0" conaffinity="0" /><geom name="planned_waypoint_159" type="sphere" pos="-0.10000 0.09909 0.07675" size="0.0032" material="planned_waypoint" contype="0" conaffinity="0" /><geom name="planned_waypoint_160" type="sphere" pos="-0.09967 0.10607 0.08078" size="0.0032" material="planned_waypoint" contype="0" conaffinity="0" /><geom name="planned_waypoint_161" type="sphere" pos="-0.09696 0.11252 0.08450" size="0.0032" material="planned_waypoint" contype="0" conaffinity="0" /><geom name="planned_waypoint_162" type="sphere" pos="-0.09006 0.11572 0.08635" size="0.0032" material="planned_waypoint" contype="0" conaffinity="0" /><geom name="planned_waypoint_163" type="sphere" pos="-0.08201 0.11622 0.08664" size="0.0032" material="planned_waypoint" contype="0" conaffinity="0" /><geom name="planned_waypoint_164" type="sphere" pos="-0.07392 0.11622 0.08664" size="0.0032" material="planned_waypoint" contype="0" conaffinity="0" /><geom name="planned_waypoint_165" type="sphere" pos="-0.06584 0.11622 0.08664" size="0.0032" material="planned_waypoint" contype="0" conaffinity="0" /><geom name="planned_waypoint_166" type="sphere" pos="-0.05775 0.11622 0.08664" size="0.0032" material="planned_waypoint" contype="0" conaffinity="0" /><geom name="planned_waypoint_167" type="sphere" pos="-0.04966 0.11622 0.08664" size="0.0032" material="planned_waypoint" contype="0" conaffinity="0" /><geom name="planned_waypoint_168" type="sphere" pos="-0.04157 0.11622 0.08664" size="0.0032" material="planned_waypoint" contype="0" conaffinity="0" /><geom name="planned_waypoint_169" type="sphere" pos="-0.03348 0.11622 0.08664" size="0.0032" material="planned_waypoint" contype="0" conaffinity="0" /><geom name="planned_waypoint_170" type="sphere" pos="-0.02540 0.11622 0.08664" size="0.0032" material="planned_waypoint" contype="0" conaffinity="0" /><geom name="planned_waypoint_171" type="sphere" pos="-0.01731 0.11622 0.08664" size="0.0032" material="planned_waypoint" contype="0" conaffinity="0" /><geom name="planned_waypoint_172" type="sphere" pos="-0.00922 0.11622 0.08664" size="0.0032" material="planned_waypoint" contype="0" conaffinity="0" /><geom name="planned_waypoint_173" type="sphere" pos="-0.00113 0.11622 0.08664" size="0.0032" material="planned_waypoint" contype="0" conaffinity="0" /><geom name="planned_waypoint_174" type="sphere" pos="0.00696 0.11622 0.08664" size="0.0032" material="planned_waypoint" contype="0" conaffinity="0" /><geom name="planned_waypoint_175" type="sphere" pos="0.01504 0.11622 0.08664" size="0.0032" material="planned_waypoint" contype="0" conaffinity="0" /><geom name="planned_waypoint_176" type="sphere" pos="0.02313 0.11622 0.08664" size="0.0032" material="planned_waypoint" contype="0" conaffinity="0" /><geom name="planned_waypoint_177" type="sphere" pos="0.03122 0.11622 0.08664" size="0.0032" material="planned_waypoint" contype="0" conaffinity="0" /><geom name="planned_waypoint_178" type="sphere" pos="0.03931 0.11622 0.08664" size="0.0032" material="planned_waypoint" contype="0" conaffinity="0" /><geom name="planned_waypoint_179" type="sphere" pos="0.04740 0.11622 0.08664" size="0.0032" material="planned_waypoint" contype="0" conaffinity="0" /><geom name="planned_waypoint_180" type="sphere" pos="0.05548 0.11622 0.08664" size="0.0032" material="planned_waypoint" contype="0" conaffinity="0" /><geom name="planned_waypoint_181" type="sphere" pos="0.06357 0.11622 0.08664" size="0.0032" material="planned_waypoint" contype="0" conaffinity="0" /><geom name="planned_waypoint_182" type="sphere" pos="0.07166 0.11622 0.08664" size="0.0032" material="planned_waypoint" contype="0" conaffinity="0" /><geom name="planned_waypoint_183" type="sphere" pos="0.07975 0.11622 0.08664" size="0.0032" material="planned_waypoint" contype="0" conaffinity="0" /><geom name="planned_waypoint_184" type="sphere" pos="0.08784 0.11622 0.08664" size="0.0032" material="planned_waypoint" contype="0" conaffinity="0" /><geom name="planned_waypoint_185" type="sphere" pos="0.09592 0.11622 0.08664" size="0.0032" material="planned_waypoint" contype="0" conaffinity="0" /><geom name="planned_waypoint_186" type="sphere" pos="0.10401 0.11622 0.08664" size="0.0032" material="planned_waypoint" contype="0" conaffinity="0" /><geom name="planned_waypoint_187" type="sphere" pos="0.11210 0.11622 0.08664" size="0.0032" material="planned_waypoint" contype="0" conaffinity="0" /><geom name="planned_waypoint_188" type="sphere" pos="0.12019 0.11622 0.08664" size="0.0032" material="planned_waypoint" contype="0" conaffinity="0" /><geom name="planned_waypoint_189" type="sphere" pos="0.12825 0.11650 0.08680" size="0.0032" material="planned_waypoint" contype="0" conaffinity="0" /><geom name="planned_waypoint_190" type="sphere" pos="0.13571 0.11884 0.08815" size="0.0032" material="planned_waypoint" contype="0" conaffinity="0" /><geom name="planned_waypoint_191" type="sphere" pos="0.13942 0.12481 0.09160" size="0.0032" material="planned_waypoint" contype="0" conaffinity="0" /><geom name="planned_waypoint_192" type="sphere" pos="0.14000 0.13178 0.09562" size="0.0032" material="planned_waypoint" contype="0" conaffinity="0" /><geom name="planned_waypoint_193" type="sphere" pos="0.14001 0.13878 0.09966" size="0.0032" material="planned_waypoint" contype="0" conaffinity="0" /><geom name="planned_waypoint_194" type="sphere" pos="0.14188 0.14549 0.10354" size="0.0032" material="planned_waypoint" contype="0" conaffinity="0" /><geom name="planned_waypoint_195" type="sphere" pos="0.14773 0.15003 0.10616" size="0.0032" material="planned_waypoint" contype="0" conaffinity="0" /><geom name="planned_waypoint_196" type="sphere" pos="0.15574 0.15086 0.10664" size="0.0032" material="planned_waypoint" contype="0" conaffinity="0" /><geom name="planned_waypoint_197" type="sphere" pos="0.16382 0.15086 0.10664" size="0.0032" material="planned_waypoint" contype="0" conaffinity="0" /><geom name="planned_waypoint_198" type="sphere" pos="0.17191 0.15086 0.10664" size="0.0032" material="planned_waypoint" contype="0" conaffinity="0" /><geom name="planned_waypoint_199" type="sphere" pos="0.18000 0.15086 0.10664" size="0.007" material="planned_goal" contype="0" conaffinity="0" /><geom name="los_path_seg_000" type="capsule" fromto="-0.18000 -0.18000 0.03300 -0.18000 -0.02000 0.03300" size="0.0035" material="los_path" contype="0" conaffinity="0" /><geom name="los_path_seg_001" type="capsule" fromto="-0.18000 -0.02000 0.03300 -0.02000 -0.02000 0.03300" size="0.0035" material="los_path" contype="0" conaffinity="0" /><geom name="los_path_seg_002" type="capsule" fromto="-0.02000 -0.02000 0.03300 -0.06000 -0.10000 0.03300" size="0.0035" material="los_path" contype="0" conaffinity="0" /><geom name="los_path_seg_003" type="capsule" fromto="-0.06000 -0.10000 0.03300 -0.10000 -0.14000 0.03300" size="0.0035" material="los_path" contype="0" conaffinity="0" /><geom name="los_path_seg_004" type="capsule" fromto="-0.10000 -0.14000 0.03300 -0.06000 -0.18000 0.03300" size="0.0035" material="los_path" contype="0" conaffinity="0" /><geom name="los_path_seg_005" type="capsule" fromto="-0.06000 -0.18000 0.03300 0.06000 -0.18000 0.03300" size="0.0035" material="los_path" contype="0" conaffinity="0" /><geom name="los_path_seg_006" type="capsule" fromto="0.06000 -0.18000 0.03300 0.10000 -0.10000 0.03300" size="0.0035" material="los_path" contype="0" conaffinity="0" /><geom name="los_path_seg_007" type="capsule" fromto="0.10000 -0.10000 0.03300 0.14000 -0.06000 0.03300" size="0.0035" material="los_path" contype="0" conaffinity="0" /><geom name="los_path_seg_008" type="capsule" fromto="0.14000 -0.06000 0.03300 0.14000 0.03944 0.05963" size="0.0035" material="los_path" contype="0" conaffinity="0" /><geom name="los_path_seg_009" type="capsule" fromto="0.14000 0.03944 0.05963 -0.10000 0.03944 0.05963" size="0.0035" material="los_path" contype="0" conaffinity="0" /><geom name="los_path_seg_010" type="capsule" fromto="-0.10000 0.03944 0.05963 -0.06000 0.10872 0.09963" size="0.0035" material="los_path" contype="0" conaffinity="0" /><geom name="los_path_seg_011" type="capsule" fromto="-0.06000 0.10872 0.09963 0.14000 0.10872 0.09963" size="0.0035" material="los_path" contype="0" conaffinity="0" /><geom name="los_path_seg_012" type="capsule" fromto="0.14000 0.10872 0.09963 0.18000 0.14336 0.11963" size="0.0035" material="los_path" contype="0" conaffinity="0" /><geom name="los_waypoint_000" type="sphere" pos="-0.18000 -0.18000 0.03300" size="0.0060" material="los_waypoint" contype="0" conaffinity="0" /><geom name="los_waypoint_001" type="sphere" pos="-0.18000 -0.02000 0.03300" size="0.0060" material="los_waypoint" contype="0" conaffinity="0" /><geom name="los_waypoint_002" type="sphere" pos="-0.02000 -0.02000 0.03300" size="0.0060" material="los_waypoint" contype="0" conaffinity="0" /><geom name="los_waypoint_003" type="sphere" pos="-0.06000 -0.10000 0.03300" size="0.0060" material="los_waypoint" contype="0" conaffinity="0" /><geom name="los_waypoint_004" type="sphere" pos="-0.10000 -0.14000 0.03300" size="0.0060" material="los_waypoint" contype="0" conaffinity="0" /><geom name="los_waypoint_005" type="sphere" pos="-0.06000 -0.18000 0.03300" size="0.0060" material="los_waypoint" contype="0" conaffinity="0" /><geom name="los_waypoint_006" type="sphere" pos="0.06000 -0.18000 0.03300" size="0.0060" material="los_waypoint" contype="0" conaffinity="0" /><geom name="los_waypoint_007" type="sphere" pos="0.10000 -0.10000 0.03300" size="0.0060" material="los_waypoint" contype="0" conaffinity="0" /><geom name="los_waypoint_008" type="sphere" pos="0.14000 -0.06000 0.03300" size="0.0060" material="los_waypoint" contype="0" conaffinity="0" /><geom name="los_waypoint_009" type="sphere" pos="0.14000 0.03944 0.05963" size="0.0060" material="los_waypoint" contype="0" conaffinity="0" /><geom name="los_waypoint_010" type="sphere" pos="-0.10000 0.03944 0.05963" size="0.0060" material="los_waypoint" contype="0" conaffinity="0" /><geom name="los_waypoint_011" type="sphere" pos="-0.06000 0.10872 0.09963" size="0.0060" material="los_waypoint" contype="0" conaffinity="0" /><geom name="los_waypoint_012" type="sphere" pos="0.14000 0.10872 0.09963" size="0.0060" material="los_waypoint" contype="0" conaffinity="0" /><geom name="los_waypoint_013" type="sphere" pos="0.18000 0.14336 0.11963" size="0.0060" material="los_waypoint" contype="0" conaffinity="0" /></body>
    <camera name="maze_view" pos="0.85 -0.85 0.80" xyaxes="0.707 0.707 0 -0.500 0.500 0.707" />
  </worldbody>
  <contact>
    <exclude body1="base_unit" body2="link1" />
    <exclude body1="link6" body2="rh_r1" />
    <exclude body1="link6" body2="rh_l1" />
    <exclude body1="link6" body2="rh_r2" />
    <exclude body1="link6" body2="rh_l2" />
    <exclude body1="rh_r1" body2="rh_r2" />
    <exclude body1="rh_l1" body2="rh_l2" />
    <exclude body1="rh_r1" body2="rh_l1" />
    <exclude body1="rh_r2" body2="rh_l2" />
    <exclude body1="link6" body2="tip" />
    <exclude body1="rh_r1" body2="tip" />
    <exclude body1="rh_l1" body2="tip" />
    <exclude body1="rh_r2" body2="tip" />
    <exclude body1="rh_l2" body2="tip" />
  </contact>
  <equality>
    <joint joint1="rh_l1" joint2="rh_r1" polycoef="0 -1 0 0 0" />
    <joint joint1="rh_r2" joint2="rh_r1" polycoef="0 -1 0 0 0" />
    <joint joint1="rh_l2" joint2="rh_r1" polycoef="0 1 0 0 0" />
  </equality>
  <keyframe>
    <key name="home" qpos="0 0 0 0 0 0 0 0 0 0" ctrl="0 0 0 0 0 0 0" />
  </keyframe>
  <actuator>
    <position class="Joint1" name="Joint1" joint="Joint1" inheritrange="1" />
    <position class="Joint2" name="Joint2" joint="Joint2" inheritrange="1" />
    <position class="Joint3" name="Joint3" joint="Joint3" inheritrange="1" />
    <position class="Joint4" name="Joint4" joint="Joint4" inheritrange="1" />
    <position class="Joint5" name="Joint5" joint="Joint5" inheritrange="1" />
    <position class="Joint6" name="Joint6" joint="Joint6" inheritrange="1" />
    <position class="Gripper" name="Gripper" joint="rh_r1" inheritrange="1" />
  </actuator>
</mujoco>