<?xml version='1.0' encoding='utf-8'?>
<mujoco model="open_manipulator_y_maze">
  <compiler angle="radian" meshdir="assets/" />
  <option cone="elliptic" impratio="10" />
  <statistic center="0.32 0 0.35" extent="1.0" />
  <visual>
    <headlight diffuse="0.6 0.6 0.6" ambient="0.3 0.3 0.3" specular="0 0 0" />
    <rgba haze="0.15 0.25 0.35 1" />
    <global azimuth="120" elevation="-20" />
  </visual>
  <asset>
    <material name="black" rgba="0.1 0.1 0.1 1" />
    <mesh name="base_unit" file="base_unit.stl" scale="0.001 0.001 0.001" />
    <mesh name="link1" file="link1.stl" scale="0.001 0.001 0.001" />
    <mesh name="link2" file="link2.stl" scale="0.001 0.001 0.001" />
    <mesh name="link3" file="link3.stl" scale="0.001 0.001 0.001" />
    <mesh name="link4" file="link4.stl" scale="0.001 0.001 0.001" />
    <mesh name="link5" file="link5.stl" scale="0.001 0.001 0.001" />
    <mesh name="link6" file="link6.stl" scale="0.001 0.001 0.001" />
    <mesh name="flange" file="flange.stl" scale="0.001 0.001 0.001" />
    <mesh name="base" file="base.stl" scale="0.001 0.001 0.001" />
    <mesh name="r1" file="r1.stl" scale="0.001 0.001 0.001" />
    <mesh name="r2" file="r2.stl" scale="0.001 0.001 0.001" />
    <mesh name="l1" file="l1.stl" scale="0.001 0.001 0.001" />
    <mesh name="l2" file="l2.stl" scale="0.001 0.001 0.001" />
    <texture type="skybox" builtin="gradient" rgb1="0.3 0.5 0.7" rgb2="0 0 0" width="512" height="3072" />
    <texture type="2d" name="groundplane" builtin="checker" mark="edge" rgb1="0.2 0.3 0.4" rgb2="0.1 0.2 0.3" markrgb="0.8 0.8 0.8" width="300" height="300" />
    <material name="groundplane" texture="groundplane" texuniform="true" texrepeat="5 5" reflectance="0.2" />
    <material name="tip_metal" rgba="0.85 0.80 0.70 1" specular="0.7" shininess="0.8" />
    <material name="tip_dark" rgba="0.04 0.04 0.04 1" />
    <material name="maze_floor" rgba="0.34 0.34 0.34 1" />
    <material name="maze_wall" rgba="0.52 0.72 0.50 0.9" />
  </asset>
  <default>
    <default class="DY_80">
      <joint frictionloss="0.1" armature="0.1" />
      <position kp="1000.0" dampratio="1.0" forcerange="-61.4 61.4" />
      <default class="Joint1">
        <joint axis="0 0 1" range="-6.283185 6.283185" />
      </default>
      <default class="Joint2">
        <joint axis="0 1 0" range="-6.283185 6.283185" />
      </default>
    </default>
    <default class="DY_70">
      <joint frictionloss="0.1" armature="0.1" />
      <position kp="1000.0" dampratio="1.0" forcerange="-31.7 31.7" />
      <default class="Joint3">
        <joint axis="0 1 0" range="-2.617994 2.617994" />
      </default>
      <default class="Joint4">
        <joint axis="0 1 0" range="-6.283185 6.283185" />
      </default>
      <default class="Joint5">
        <joint axis="0 0 1" range="-6.283185 6.283185" />
      </default>
      <default class="Joint6">
        <joint axis="0 1 0" range="-6.283185 6.283185" />
      </default>
    </default>
    <default class="DX">
      <joint frictionloss="0.1" armature="0.1" damping="1.0" />
      <position kp="50" dampratio="1" forcerange="-3.5 3.5" />
      <default class="Gripper">
        <joint axis="1 0 0" range="0 1.1" />
      </default>
      <default class="Gripper_mimic">
        <joint axis="1 0 0" range="-1.1 0" />
      </default>
      <default class="Gripper_mimic_pos">
        <joint axis="1 0 0" range="0 1.1" />
      </default>
    </default>
    <default class="visual">
      <geom type="mesh" contype="0" conaffinity="0" density="0" group="2" material="black" />
    </default>
    <default class="collision">
      <geom group="3" type="mesh" material="black" contype="0" conaffinity="0" />
    </default>
  </default>
  <worldbody>
    <light name="main_light" pos="0 0 1.5" dir="0 0 -1" directional="true" />
    <geom name="floor" size="0 0 0.05" type="plane" material="groundplane" />
    <body name="base_unit">
      <geom mesh="base_unit" class="visual" />
      <geom mesh="base_unit" class="collision" />
      <body name="link1" pos="0 0 0.1715">
        <inertial pos="-0.000110636 -0.00547113 -0.0158977" quat="0.98558 0.168758 -0.00294757 0.0120358" mass="2.06488" diaginertia="0.00303337 0.00279081 0.00221937" />
        <joint name="Joint1" class="Joint1" />
        <geom mesh="link1" class="visual" />
        <geom mesh="link1" class="collision" />
        <body name="link2" pos="0 -0.1215 0">
          <inertial pos="1.14054e-05 0.0161842 0.103606" quat="0.999988 -0.00477885 -0.000609836 0.00067321" mass="3.67954" diaginertia="0.051732 0.0503576 0.00449718" />
          <joint name="Joint2" class="Joint2" />
          <geom mesh="link2" class="visual" />
          <geom mesh="link2" class="collision" />
          <body name="link3" pos="0 0 0.247">
            <inertial pos="7.81487e-05 0.107185 0.141173" quat="0.999987 0.00500823 0.000469041 -0.00072733" mass="2.38659" diaginertia="0.0226944 0.021922 0.00277422" />
            <joint name="Joint3" class="Joint3" />
            <geom mesh="link3" class="visual" />
            <geom mesh="link3" class="collision" />
            <body name="link4" pos="0 0.1215 0.2195">
              <inertial pos="-0.000133183 -0.107467 0.0190907" quat="0.983636 0.179196 0.00338061 -0.0183488" mass="1.40023" diaginertia="0.00175475 0.00162284 0.00115817" />
              <joint name="Joint4" class="Joint4" />
              <geom mesh="link4" class="visual" />
              <geom mesh="link4" class="collision" />
              <body name="link5" pos="0 -0.113 0">
                <inertial pos="0.000133183 -0.0190907 0.109967" quat="0.822247 0.568825 0.0105841 -0.015365" mass="1.40023" diaginertia="0.00175475 0.00162284 0.00115817" />
                <joint name="Joint5" class="Joint5" />
                <geom mesh="link5" class="visual" />
                <geom mesh="link5" class="collision" />
                <body name="link6" pos="0 0 0.1155">
                  <inertial pos="1.6005e-05 -0.103085 0.00570277" quat="0.456875 0.889528 0.00170634 -0.00130773" mass="0.652774" diaginertia="0.00112656 0.000847594 0.000551829" />
                  <joint name="Joint6" class="Joint6" />
                  <geom mesh="link6" class="visual" />
                  <geom mesh="link6" class="collision" />
                  <geom pos="0 -0.103 0" mesh="flange" class="visual" />
                  <geom pos="0 -0.103 0" mesh="flange" class="collision" />
                  <geom pos="0 -0.109 0" quat="0.500398 0.5 0.5 -0.499602" mesh="base" class="visual" />
                  <geom pos="0 -0.109 0" quat="0.500398 0.5 0.5 -0.499602" mesh="base" class="collision" />
                  <body name="rh_r1" pos="0.00803822 -0.156994 6.40105e-06" quat="0.500398 0.5 0.5 -0.499602">
                    <inertial pos="0 0.034 0.004" mass="0.068" diaginertia="1e-06 1e-06 1e-06" />
                    <joint name="rh_r1" class="Gripper" />
                    <geom mesh="r1" class="visual" />
                    <geom mesh="r1" class="collision" />
                    <body name="rh_r2" pos="0 0.0493634 0.0285">
                      <inertial pos="0 0.006 0.011" mass="0.022" diaginertia="1e-06 1e-06 1e-06" />
                      <joint name="rh_r2" class="Gripper_mimic" />
                      <geom mesh="r2" class="visual" />
                      <geom mesh="r2" class="collision" />
                    </body>
                  </body>
                  <body name="rh_l1" pos="-0.00796177 -0.157006 -6.34017e-06" quat="0.500398 0.5 0.5 -0.499602">
                    <inertial pos="0 -0.034 0.004" mass="0.068" diaginertia="1e-06 1e-06 1e-06" />
                    <joint name="rh_l1" class="Gripper_mimic" />
                    <geom mesh="l1" class="visual" />
                    <geom mesh="l1" class="collision" />
                    <body name="rh_l2" pos="0 -0.0493634 0.0285">
                      <inertial pos="0 -0.006 0.011" mass="0.022" diaginertia="1e-06 1e-06 1e-06" />
                      <joint name="rh_l2" class="Gripper_mimic_pos" />
                      <geom mesh="l2" class="visual" />
                      <geom mesh="l2" class="collision" />
                    </body>
                  </body>
                  <body name="tip" pos="0 -0.315 0">
                    <inertial pos="0 0.055 0" mass="0.015" diaginertia="1e-5 1e-5 1e-5" />
                    <geom name="tip_mount" type="capsule" fromto="0 0.125 0 0 0.095 0" size="0.012" material="tip_dark" contype="0" conaffinity="0" density="0" />
                    <geom name="tip_shaft" type="capsule" fromto="0 0.105 0 0 0.000 0" size="0.004" material="tip_metal" contype="0" conaffinity="0" condim="3" friction="1 0.005 0.0001" density="0" />
                    <site name="tip_site" pos="0 0 0" size="0.007" rgba="1 0.1 0.1 1" />
                  </body>
                </body>
              </body>
            </body>
          </body>
        </body>
      </body>
    </body>
    <body name="maze" pos="0.3400 0.0000 0.0000">
      <geom name="maze_floor_flat_right" type="box" pos="0.0000 -0.1200 0.0040" size="0.2400 0.1200 0.0040" material="maze_floor" contype="1" conaffinity="1" friction="1 0.005 0.0001" />
      <geom name="maze_floor_folded_left_30deg" type="box" pos="0.0000 0.1059 0.0645" quat="0.9659258263 0.2588190451 0 0" size="0.2400 0.1200 0.0040" material="maze_floor" contype="1" conaffinity="1" friction="1 0.005 0.0001" />
      <geom name="maze_fold_hinge_axis" type="cylinder" pos="0.0000 0.0000 0.0080" quat="0.7071067812 0 0.7071067812 0" size="0.0040 0.2450" material="tip_metal" contype="0" conaffinity="0" />
      <site name="maze_origin_ll" pos="-0.2400 -0.2400 0.0130" size="0.0060" rgba="0.1 0.1 1.0 1" />
      <site name="maze_entrance" pos="-0.1800 -0.2200 0.0130" size="0.0060" rgba="0.1 0.6 1.0 1" />
      <site name="maze_start" pos="-0.1000 -0.1800 0.0130" size="0.0080" rgba="0.1 0.9 0.1 1" />
      <site name="maze_goal" pos="-0.1000 -0.1300 0.0130" size="0.0080" rgba="0.9 0.1 0.1 1" />
      <geom name="maze_start_marker" type="sphere" pos="-0.1000 -0.1800 0.0180" size="0.0090" rgba="0.0 1.0 0.0 1" contype="0" conaffinity="0" />
      <geom name="maze_goal_marker" type="sphere" pos="-0.1000 -0.1300 0.0180" size="0.0090" rgba="1.0 0.0 0.0 1" contype="0" conaffinity="0" />
      <site name="maze_exit" pos="0.1800 0.1880 0.1223" size="0.0060" rgba="1.0 0.6 0.1 1" />
      <site name="maze_fold_hinge_center" pos="0.0000 0.0000 0.0080" size="0.0060" rgba="0.8 0.8 0.1 1" />
    <geom name="maze_cube_r00_c00" type="box" pos="-0.2200 -0.2200 0.0280" size="0.0200 0.0200 0.0200" material="maze_wall" contype="1" conaffinity="1" friction="1 0.005 0.0001" /><geom name="maze_cube_r00_c02" type="box" pos="-0.1400 -0.2200 0.0280" size="0.0200 0.0200 0.0200" material="maze_wall" contype="1" conaffinity="1" friction="1 0.005 0.0001" /><geom name="maze_cube_r00_c03" type="box" pos="-0.1000 -0.2200 0.0280" size="0.0200 0.0200 0.0200" material="maze_wall" contype="1" conaffinity="1" friction="1 0.005 0.0001" /><geom name="maze_cube_r00_c04" type="box" pos="-0.0600 -0.2200 0.0280" size="0.0200 0.0200 0.0200" material="maze_wall" contype="1" conaffinity="1" friction="1 0.005 0.0001" /><geom name="maze_cube_r00_c05" type="box" pos="-0.0200 -0.2200 0.0280" size="0.0200 0.0200 0.0200" material="maze_wall" contype="1" conaffinity="1" friction="1 0.005 0.0001" /><geom name="maze_cube_r00_c06" type="box" pos="0.0200 -0.2200 0.0280" size="0.0200 0.0200 0.0200" material="maze_wall" contype="1" conaffinity="1" friction="1 0.005 0.0001" /><geom name="maze_cube_r00_c07" type="box" pos="0.0600 -0.2200 0.0280" size="0.0200 0.0200 0.0200" material="maze_wall" contype="1" conaffinity="1" friction="1 0.005 0.0001" /><geom name="maze_cube_r00_c08" type="box" pos="0.1000 -0.2200 0.0280" size="0.0200 0.0200 0.0200" material="maze_wall" contype="1" conaffinity="1" friction="1 0.005 0.0001" /><geom name="maze_cube_r00_c09" type="box" pos="0.1400 -0.2200 0.0280" size="0.0200 0.0200 0.0200" material="maze_wall" contype="1" conaffinity="1" friction="1 0.005 0.0001" /><geom name="maze_cube_r00_c10" type="box" pos="0.1800 -0.2200 0.0280" size="0.0200 0.0200 0.0200" material="maze_wall" contype="1" conaffinity="1" friction="1 0.005 0.0001" /><geom name="maze_cube_r00_c11" type="box" pos="0.2200 -0.2200 0.0280" size="0.0200 0.0200 0.0200" material="maze_wall" contype="1" conaffinity="1" friction="1 0.005 0.0001" /><geom name="maze_cube_r01_c00" type="box" pos="-0.2200 -0.1800 0.0280" size="0.0200 0.0200 0.0200" material="maze_wall" contype="1" conaffinity="1" friction="1 0.005 0.0001" /><geom name="maze_cube_r01_c04" type="box" pos="-0.0600 -0.1800 0.0280" size="0.0200 0.0200 0.0200" material="maze_wall" contype="1" conaffinity="1" friction="1 0.005 0.0001" /><geom name="maze_cube_r01_c10" type="box" pos="0.1800 -0.1800 0.0280" size="0.0200 0.0200 0.0200" material="maze_wall" contype="1" conaffinity="1" friction="1 0.005 0.0001" /><geom name="maze_cube_r01_c11" type="box" pos="0.2200 -0.1800 0.0280" size="0.0200 0.0200 0.0200" material="maze_wall" contype="1" conaffinity="1" friction="1 0.005 0.0001" /><geom name="maze_cube_r02_c00" type="box" pos="-0.2200 -0.1400 0.0280" size="0.0200 0.0200 0.0200" material="maze_wall" contype="1" conaffinity="1" friction="1 0.005 0.0001" /><geom name="maze_cube_r02_c01" type="box" pos="-0.1800 -0.1400 0.0280" size="0.0200 0.0200 0.0200" material="maze_wall" contype="1" conaffinity="1" friction="1 0.005 0.0001" /><geom name="maze_cube_r02_c02" type="box" pos="-0.1400 -0.1400 0.0280" size="0.0200 0.0200 0.0200" material="maze_wall" contype="1" conaffinity="1" friction="1 0.005 0.0001" /><geom name="maze_cube_r02_c04" type="box" pos="-0.0600 -0.1400 0.0280" size="0.0200 0.0200 0.0200" material="maze_wall" contype="1" conaffinity="1" friction="1 0.005 0.0001" /><geom name="maze_cube_r02_c05" type="box" pos="-0.0200 -0.1400 0.0280" size="0.0200 0.0200 0.0200" material="maze_wall" contype="1" conaffinity="1" friction="1 0.005 0.0001" /><geom name="maze_cube_r02_c06" type="box" pos="0.0200 -0.1400 0.0280" size="0.0200 0.0200 0.0200" material="maze_wall" contype="1" conaffinity="1" friction="1 0.005 0.0001" /><geom name="maze_cube_r02_c07" type="box" pos="0.0600 -0.1400 0.0280" size="0.0200 0.0200 0.0200" material="maze_wall" contype="1" conaffinity="1" friction="1 0.005 0.0001" /><geom name="maze_cube_r02_c08" type="box" pos="0.1000 -0.1400 0.0280" size="0.0200 0.0200 0.0200" material="maze_wall" contype="1" conaffinity="1" friction="1 0.005 0.0001" /><geom name="maze_cube_r02_c10" type="box" pos="0.1800 -0.1400 0.0280" size="0.0200 0.0200 0.0200" material="maze_wall" contype="1" conaffinity="1" friction="1 0.005 0.0001" /><geom name="maze_cube_r02_c11" type="box" pos="0.2200 -0.1400 0.0280" size="0.0200 0.0200 0.0200" material="maze_wall" contype="1" conaffinity="1" friction="1 0.005 0.0001" /><geom name="maze_cube_r03_c00" type="box" pos="-0.2200 -0.1000 0.0280" size="0.0200 0.0200 0.0200" material="maze_wall" contype="1" conaffinity="1" friction="1 0.005 0.0001" /><geom name="maze_cube_r03_c02" type="box" pos="-0.1400 -0.1000 0.0280" size="0.0200 0.0200 0.0200" material="maze_wall" contype="1" conaffinity="1" friction="1 0.005 0.0001" /><geom name="maze_cube_r03_c08" type="box" pos="0.1000 -0.1000 0.0280" size="0.0200 0.0200 0.0200" material="maze_wall" contype="1" conaffinity="1" friction="1 0.005 0.0001" /><geom name="maze_cube_r03_c10" type="box" pos="0.1800 -0.1000 0.0280" size="0.0200 0.0200 0.0200" material="maze_wall" contype="1" conaffinity="1" friction="1 0.005 0.0001" /><geom name="maze_cube_r03_c11" type="box" pos="0.2200 -0.1000 0.0280" size="0.0200 0.0200 0.0200" material="maze_wall" contype="1" conaffinity="1" friction="1 0.005 0.0001" /><geom name="maze_cube_r04_c00" type="box" pos="-0.2200 -0.0600 0.0280" size="0.0200 0.0200 0.0200" material="maze_wall" contype="1" conaffinity="1" friction="1 0.005 0.0001" /><geom name="maze_cube_r04_c02" type="box" pos="-0.1400 -0.0600 0.0280" size="0.0200 0.0200 0.0200" material="maze_wall" contype="1" conaffinity="1" friction="1 0.005 0.0001" /><geom name="maze_cube_r04_c03" type="box" pos="-0.1000 -0.0600 0.0280" size="0.0200 0.0200 0.0200" material="maze_wall" contype="1" conaffinity="1" friction="1 0.005 0.0001" /><geom name="maze_cube_r04_c04" type="box" pos="-0.0600 -0.0600 0.0280" size="0.0200 0.0200 0.0200" material="maze_wall" contype="1" conaffinity="1" friction="1 0.005 0.0001" /><geom name="maze_cube_r04_c05" type="box" pos="-0.0200 -0.0600 0.0280" size="0.0200 0.0200 0.0200" material="maze_wall" contype="1" conaffinity="1" friction="1 0.005 0.0001" /><geom name="maze_cube_r04_c06" type="box" pos="0.0200 -0.0600 0.0280" size="0.0200 0.0200 0.0200" material="maze_wall" contype="1" conaffinity="1" friction="1 0.005 0.0001" /><geom name="maze_cube_r04_c08" type="box" pos="0.1000 -0.0600 0.0280" size="0.0200 0.0200 0.0200" material="maze_wall" contype="1" conaffinity="1" friction="1 0.005 0.0001" /><geom name="maze_cube_r04_c10" type="box" pos="0.1800 -0.0600 0.0280" size="0.0200 0.0200 0.0200" material="maze_wall" contype="1" conaffinity="1" friction="1 0.005 0.0001" /><geom name="maze_cube_r04_c11" type="box" pos="0.2200 -0.0600 0.0280" size="0.0200 0.0200 0.0200" material="maze_wall" contype="1" conaffinity="1" friction="1 0.005 0.0001" /><geom name="maze_cube_r05_c00" type="box" pos="-0.2200 -0.0200 0.0280" size="0.0200 0.0200 0.0200" material="maze_wall" contype="1" conaffinity="1" friction="1 0.005 0.0001" /><geom name="maze_cube_r05_c06" type="box" pos="0.0200 -0.0200 0.0280" size="0.0200 0.0200 0.0200" material="maze_wall" contype="1" conaffinity="1" friction="1 0.005 0.0001" /><geom name="maze_cube_r05_c08" type="box" pos="0.1000 -0.0200 0.0280" size="0.0200 0.0200 0.0200" material="maze_wall" contype="1" conaffinity="1" friction="1 0.005 0.0001" /><geom name="maze_cube_r05_c10" type="box" pos="0.1800 -0.0200 0.0280" size="0.0200 0.0200 0.0200" material="maze_wall" contype="1" conaffinity="1" friction="1 0.005 0.0001" /><geom name="maze_cube_r05_c11" type="box" pos="0.2200 -0.0200 0.0280" size="0.0200 0.0200 0.0200" material="maze_wall" contype="1" conaffinity="1" friction="1 0.005 0.0001" /><geom name="maze_cube_r06_c00" type="box" pos="-0.2200 0.0073 0.0353" quat="0.9659258263 0.2588190451 0 0" size="0.0200 0.0200 0.0200" material="maze_wall" contype="1" conaffinity="1" friction="1 0.005 0.0001" /><geom name="maze_cube_r06_c02" type="box" pos="-0.1400 0.0073 0.0353" quat="0.9659258263 0.2588190451 0 0" size="0.0200 0.0200 0.0200" material="maze_wall" contype="1" conaffinity="1" friction="1 0.005 0.0001" /><geom name="maze_cube_r06_c04" type="box" pos="-0.0600 0.0073 0.0353" quat="0.9659258263 0.2588190451 0 0" size="0.0200 0.0200 0.0200" material="maze_wall" contype="1" conaffinity="1" friction="1 0.005 0.0001" /><geom name="maze_cube_r06_c05" type="box" pos="-0.0200 0.0073 0.0353" quat="0.9659258263 0.2588190451 0 0" size="0.0200 0.0200 0.0200" material="maze_wall" contype="1" conaffinity="1" friction="1 0.005 0.0001" /><geom name="maze_cube_r06_c06" type="box" pos="0.0200 0.0073 0.0353" quat="0.9659258263 0.2588190451 0 0" size="0.0200 0.0200 0.0200" material="maze_wall" contype="1" conaffinity="1" friction="1 0.005 0.0001" /><geom name="maze_cube_r06_c08" type="box" pos="0.1000 0.0073 0.0353" quat="0.9659258263 0.2588190451 0 0" size="0.0200 0.0200 0.0200" material="maze_wall" contype="1" conaffinity="1" friction="1 0.005 0.0001" /><geom name="maze_cube_r06_c10" type="box" pos="0.1800 0.0073 0.0353" quat="0.9659258263 0.2588190451 0 0" size="0.0200 0.0200 0.0200" material="maze_wall" contype="1" conaffinity="1" friction="1 0.005 0.0001" /><geom name="maze_cube_r06_c11" type="box" pos="0.2200 0.0073 0.0353" quat="0.9659258263 0.2588190451 0 0" size="0.0200 0.0200 0.0200" material="maze_wall" contype="1" conaffinity="1" friction="1 0.005 0.0001" /><geom name="maze_cube_r07_c00" type="box" pos="-0.2200 0.0419 0.0553" quat="0.9659258263 0.2588190451 0 0" size="0.0200 0.0200 0.0200" material="maze_wall" contype="1" conaffinity="1" friction="1 0.005 0.0001" /><geom name="maze_cube_r07_c02" type="box" pos="-0.1400 0.0419 0.0553" quat="0.9659258263 0.2588190451 0 0" size="0.0200 0.0200 0.0200" material="maze_wall" contype="1" conaffinity="1" friction="1 0.005 0.0001" /><geom name="maze_cube_r07_c04" type="box" pos="-0.0600 0.0419 0.0553" quat="0.9659258263 0.2588190451 0 0" size="0.0200 0.0200 0.0200" material="maze_wall" contype="1" conaffinity="1" friction="1 0.005 0.0001" /><geom name="maze_cube_r07_c08" type="box" pos="0.1000 0.0419 0.0553" quat="0.9659258263 0.2588190451 0 0" size="0.0200 0.0200 0.0200" material="maze_wall" contype="1" conaffinity="1" friction="1 0.005 0.0001" /><geom name="maze_cube_r07_c10" type="box" pos="0.1800 0.0419 0.0553" quat="0.9659258263 0.2588190451 0 0" size="0.0200 0.0200 0.0200" material="maze_wall" contype="1" conaffinity="1" friction="1 0.005 0.0001" /><geom name="maze_cube_r07_c11" type="box" pos="0.2200 0.0419 0.0553" quat="0.9659258263 0.2588190451 0 0" size="0.0200 0.0200 0.0200" material="maze_wall" contype="1" conaffinity="1" friction="1 0.005 0.0001" /><geom name="maze_cube_r08_c00" type="box" pos="-0.2200 0.0766 0.0753" quat="0.9659258263 0.2588190451 0 0" size="0.0200 0.0200 0.0200" material="maze_wall" contype="1" conaffinity="1" friction="1 0.005 0.0001" /><geom name="maze_cube_r08_c02" type="box" pos="-0.1400 0.0766 0.0753" quat="0.9659258263 0.2588190451 0 0" size="0.0200 0.0200 0.0200" material="maze_wall" contype="1" conaffinity="1" friction="1 0.005 0.0001" /><geom name="maze_cube_r08_c04" type="box" pos="-0.0600 0.0766 0.0753" quat="0.9659258263 0.2588190451 0 0" size="0.0200 0.0200 0.0200" material="maze_wall" contype="1" conaffinity="1" friction="1 0.005 0.0001" /><geom name="maze_cube_r08_c06" type="box" pos="0.0200 0.0766 0.0753" quat="0.9659258263 0.2588190451 0 0" size="0.0200 0.0200 0.0200" material="maze_wall" contype="1" conaffinity="1" friction="1 0.005 0.0001" /><geom name="maze_cube_r08_c07" type="box" pos="0.0600 0.0766 0.0753" quat="0.9659258263 0.2588190451 0 0" size="0.0200 0.0200 0.0200" material="maze_wall" contype="1" conaffinity="1" friction="1 0.005 0.0001" /><geom name="maze_cube_r08_c08" type="box" pos="0.1000 0.0766 0.0753" quat="0.9659258263 0.2588190451 0 0" size="0.0200 0.0200 0.0200" material="maze_wall" contype="1" conaffinity="1" friction="1 0.005 0.0001" /><geom name="maze_cube_r08_c10" type="box" pos="0.1800 0.0766 0.0753" quat="0.9659258263 0.2588190451 0 0" size="0.0200 0.0200 0.0200" material="maze_wall" contype="1" conaffinity="1" friction="1 0.005 0.0001" /><geom name="maze_cube_r08_c11" type="box" pos="0.2200 0.0766 0.0753" quat="0.9659258263 0.2588190451 0 0" size="0.0200 0.0200 0.0200" material="maze_wall" contype="1" conaffinity="1" friction="1 0.005 0.0001" /><geom name="maze_cube_r09_c00" type="box" pos="-0.2200 0.1112 0.0953" quat="0.9659258263 0.2588190451 0 0" size="0.0200 0.0200 0.0200" material="maze_wall" contype="1" conaffinity="1" friction="1 0.005 0.0001" /><geom name="maze_cube_r09_c02" type="box" pos="-0.1400 0.1112 0.0953" quat="0.9659258263 0.2588190451 0 0" size="0.0200 0.0200 0.0200" material="maze_wall" contype="1" conaffinity="1" friction="1 0.005 0.0001" /><geom name="maze_cube_r09_c11" type="box" pos="0.2200 0.1112 0.0953" quat="0.9659258263 0.2588190451 0 0" size="0.0200 0.0200 0.0200" material="maze_wall" contype="1" conaffinity="1" friction="1 0.005 0.0001" /><geom name="maze_cube_r10_c00" type="box" pos="-0.2200 0.1459 0.1153" quat="0.9659258263 0.2588190451 0 0" size="0.0200 0.0200 0.0200" material="maze_wall" contype="1" conaffinity="1" friction="1 0.005 0.0001" /><geom name="maze_cube_r10_c01" type="box" pos="-0.1800 0.1459 0.1153" quat="0.9659258263 0.2588190451 0 0" size="0.0200 0.0200 0.0200" material="maze_wall" contype="1" conaffinity="1" friction="1 0.005 0.0001" /><geom name="maze_cube_r10_c02" type="box" pos="-0.1400 0.1459 0.1153" quat="0.9659258263 0.2588190451 0 0" size="0.0200 0.0200 0.0200" material="maze_wall" contype="1" conaffinity="1" friction="1 0.005 0.0001" /><geom name="maze_cube_r10_c03" type="box" pos="-0.1000 0.1459 0.1153" quat="0.9659258263 0.2588190451 0 0" size="0.0200 0.0200 0.0200" material="maze_wall" contype="1" conaffinity="1" friction="1 0.005 0.0001" /><geom name="maze_cube_r10_c04" type="box" pos="-0.0600 0.1459 0.1153" quat="0.9659258263 0.2588190451 0 0" size="0.0200 0.0200 0.0200" material="maze_wall" contype="1" conaffinity="1" friction="1 0.005 0.0001" /><geom name="maze_cube_r10_c05" type="box" pos="-0.0200 0.1459 0.1153" quat="0.9659258263 0.2588190451 0 0" size="0.0200 0.0200 0.0200" material="maze_wall" contype="1" conaffinity="1" friction="1 0.005 0.0001" /><geom name="maze_cube_r10_c06" type="box" pos="0.0200 0.1459 0.1153" quat="0.9659258263 0.2588190451 0 0" size="0.0200 0.0200 0.0200" material="maze_wall" contype="1" conaffinity="1" friction="1 0.005 0.0001" /><geom name="maze_cube_r10_c07" type="box" pos="0.0600 0.1459 0.1153" quat="0.9659258263 0.2588190451 0 0" size="0.0200 0.0200 0.0200" material="maze_wall" contype="1" conaffinity="1" friction="1 0.005 0.0001" /><geom name="maze_cube_r10_c08" type="box" pos="0.1000 0.1459 0.1153" quat="0.9659258263 0.2588190451 0 0" size="0.0200 0.0200 0.0200" material="maze_wall" contype="1" conaffinity="1" friction="1 0.005 0.0001" /><geom name="maze_cube_r10_c09" type="box" pos="0.1400 0.1459 0.1153" quat="0.9659258263 0.2588190451 0 0" size="0.0200 0.0200 0.0200" material="maze_wall" contype="1" conaffinity="1" friction="1 0.005 0.0001" /><geom name="maze_cube_r10_c11" type="box" pos="0.2200 0.1459 0.1153" quat="0.9659258263 0.2588190451 0 0" size="0.0200 0.0200 0.0200" material="maze_wall" contype="1" conaffinity="1" friction="1 0.005 0.0001" /><geom name="maze_cube_r11_c00" type="box" pos="-0.2200 0.1805 0.1353" quat="0.9659258263 0.2588190451 0 0" size="0.0200 0.0200 0.0200" material="maze_wall" contype="1" conaffinity="1" friction="1 0.005 0.0001" /><geom name="maze_cube_r11_c01" type="box" pos="-0.1800 0.1805 0.1353" quat="0.9659258263 0.2588190451 0 0" size="0.0200 0.0200 0.0200" material="maze_wall" contype="1" conaffinity="1" friction="1 0.005 0.0001" /><geom name="maze_cube_r11_c02" type="box" pos="-0.1400 0.1805 0.1353" quat="0.9659258263 0.2588190451 0 0" size="0.0200 0.0200 0.0200" material="maze_wall" contype="1" conaffinity="1" friction="1 0.005 0.0001" /><geom name="maze_cube_r11_c03" type="box" pos="-0.1000 0.1805 0.1353" quat="0.9659258263 0.2588190451 0 0" size="0.0200 0.0200 0.0200" material="maze_wall" contype="1" conaffinity="1" friction="1 0.005 0.0001" /><geom name="maze_cube_r11_c04" type="box" pos="-0.0600 0.1805 0.1353" quat="0.9659258263 0.2588190451 0 0" size="0.0200 0.0200 0.0200" material="maze_wall" contype="1" conaffinity="1" friction="1 0.005 0.0001" /><geom name="maze_cube_r11_c05" type="box" pos="-0.0200 0.1805 0.1353" quat="0.9659258263 0.2588190451 0 0" size="0.0200 0.0200 0.0200" material="maze_wall" contype="1" conaffinity="1" friction="1 0.005 0.0001" /><geom name="maze_cube_r11_c06" type="box" pos="0.0200 0.1805 0.1353" quat="0.9659258263 0.2588190451 0 0" size="0.0200 0.0200 0.0200" material="maze_wall" contype="1" conaffinity="1" friction="1 0.005 0.0001" /><geom name="maze_cube_r11_c07" type="box" pos="0.0600 0.1805 0.1353" quat="0.9659258263 0.2588190451 0 0" size="0.0200 0.0200 0.0200" material="maze_wall" contype="1" conaffinity="1" friction="1 0.005 0.0001" /><geom name="maze_cube_r11_c08" type="box" pos="0.1000 0.1805 0.1353" quat="0.9659258263 0.2588190451 0 0" size="0.0200 0.0200 0.0200" material="maze_wall" contype="1" conaffinity="1" friction="1 0.005 0.0001" /><geom name="maze_cube_r11_c09" type="box" pos="0.1400 0.1805 0.1353" quat="0.9659258263 0.2588190451 0 0" size="0.0200 0.0200 0.0200" material="maze_wall" contype="1" conaffinity="1" friction="1 0.005 0.0001" /><geom name="maze_cube_r11_c11" type="box" pos="0.2200 0.1805 0.1353" quat="0.9659258263 0.2588190451 0 0" size="0.0200 0.0200 0.0200" material="maze_wall" contype="1" conaffinity="1" friction="1 0.005 0.0001" /></body>
    <camera name="maze_view" pos="0.85 -0.85 0.80" xyaxes="0.707 0.707 0 -0.500 0.500 0.707" />
  </worldbody>
  <contact>
    <exclude body1="base_unit" body2="link1" />
    <exclude body1="link6" body2="rh_r1" />
    <exclude body1="link6" body2="rh_l1" />
    <exclude body1="link6" body2="rh_r2" />
    <exclude body1="link6" body2="rh_l2" />
    <exclude body1="rh_r1" body2="rh_r2" />
    <exclude body1="rh_l1" body2="rh_l2" />
    <exclude body1="rh_r1" body2="rh_l1" />
    <exclude body1="rh_r2" body2="rh_l2" />
    <exclude body1="link6" body2="tip" />
    <exclude body1="rh_r1" body2="tip" />
    <exclude body1="rh_l1" body2="tip" />
    <exclude body1="rh_r2" body2="tip" />
    <exclude body1="rh_l2" body2="tip" />
  </contact>
  <equality>
    <joint joint1="rh_l1" joint2="rh_r1" polycoef="0 -1 0 0 0" />
    <joint joint1="rh_r2" joint2="rh_r1" polycoef="0 -1 0 0 0" />
    <joint joint1="rh_l2" joint2="rh_r1" polycoef="0 1 0 0 0" />
  </equality>
  <keyframe>
    <key name="home" qpos="0 0 0 0 0 0 0 0 0 0" ctrl="0 0 0 0 0 0 0" />
  </keyframe>
  <actuator>
    <position class="Joint1" name="Joint1" joint="Joint1" inheritrange="1" />
    <position class="Joint2" name="Joint2" joint="Joint2" inheritrange="1" />
    <position class="Joint3" name="Joint3" joint="Joint3" inheritrange="1" />
    <position class="Joint4" name="Joint4" joint="Joint4" inheritrange="1" />
    <position class="Joint5" name="Joint5" joint="Joint5" inheritrange="1" />
    <position class="Joint6" name="Joint6" joint="Joint6" inheritrange="1" />
    <position class="Gripper" name="Gripper" joint="rh_r1" inheritrange="1" />
  </actuator>
</mujoco>